Workbook

Sheet README
B2: April DIY Pricing 2.0 Calculator
B3: Rebuilt from the Notion memo 'april Pricing 2.0 (v2): DIY Standard Framework, Pro Bespoke' (last edited 2026-06-25).
B5: How to use
B6: 1. Inputs | C6: Set the rate-engine drivers. Every blue cell is editable; everything else is a formula.
B7: 2. Deal Calculator | C7: The working tool. Enter a minimum commitment, a forecast volume, a platform tier and any discount; read the bill.
B8: 3. Rate Matrix | C8: The published rate card: volume band x minimum commitment. Recomputes from Inputs.
B9: 4. Blended Rate Grid | C9: Effective $/filing by commitment and forecast volume, i.e. the waterfall.
B10: 5. Platform Tiers | C10: Scale / Growth / Enterprise fees and the service levels attached to them.
B12: Colour convention
B13: Blue text | C13: Hardcoded input. Edit these.
B14: Black text | C14: Formula. Do not overwrite.
B15: Green text | C15: Link to another sheet in this workbook.
B16: Yellow fill | C16: Key assumption or the cell you are meant to fill in on the Deal Calculator.
B18: The pricing model in one paragraph
C19: Every DIY deal is two independent choices. (1) A platform fee, tied to service level, billed monthly. (2) A minimum unit commitment, which drives the per-filing rate: a larger commitment unlocks a larger discount. The rate card starts at the entry rate for the first volume band and steps down by a fixed dollar amount per band. Each additional 10K of minimum commitment prices a fixed percent below the prior column, compounding. Every rate clamps at the absolute floor and rounds to the nearest $0.10. Volume is billed as a waterfall through the bands, so as actual volume rises the blended effective rate falls further.
B21: Rules carried over from the memo
C22: - Tiered model only. No flat per-filing fees; flat pricing requires COO approval.
C23: - Discounts must be a percentage off the tier rate. Campfire can only bill percentage discounts, so dollar-step adjustments are out.
C24: - There is no Starter tier. Anything under the Scale minimum is steered up to Scale or handled off-framework.
C25: - Volume below the committed minimum bills at the minimum.
C26: - Sweet spot is roughly 40% of usage above the committed minimum in Year 1 and 20% in Year 2. Coming in below the minimum triggers a renegotiation.
C27: - Pro and Pro Review are bespoke, enterprise-level deals. This calculator is DIY only; use it as a starting point for Pro, then negotiate.
B29: Known variance vs the published matrix
C30: One cell differs by $0.10. At the 0-25,000 band and a 30K commitment the engine computes $25.00 x 0.9^2 = $20.25, an exact half-cent tie, which Excel rounds up to $20.30 while the memo's matrix prints $20.20. Every other cell in the published matrix reproduces exactly. Flagged rather than fudged: change the rounding rule on Inputs if you want the memo's value.
B32: Open questions from the memo (unresolved, not modelled here)
C33: - Platform fee derivation: no data-driven method yet, acknowledged gap.
C34: - Seasonal-only payment pushback (Robinhood, Jackson Hewitt want to pay Jan-Apr only). Needs guardrails.
C35: - Year-2+ justification: decouple the platform fee rationale from implementation support.
C36: - Below-minimum trigger: codify the renegotiation rule.
C37: - DIY unit cost: need fully loaded cost per filing to confirm the $7.00 floor clears the margin target.

Sheet Inputs
B2: Rate engine inputs
B3: Every blue cell drives the Rate Matrix, the Blended Rate Grid and the Deal Calculator.
B5: Driver | C5: Value | D5: Format | E5: Note
B6: Entry rate (first band, lowest commit) | C6: 25 | D6: input | E6: Base column top-left of the rate card.
B7: Band step-down (per volume band) | C7: -2 | D7: input | E7: The base column steps down this much per band: $25 / $23 / $21 / $19 / $17.
B8: Discount per commitment step | C8: 0.1 | D8: input | E8: Each higher commitment column prices this percent below the prior one, compounding.
B9: Commitment step size (filings) | C9: 10000 | D9: input | E9: 10% per 10K of commitment.
B10: Base commitment (matrix column 1) | C10: 10000 | D10: input | E10: The commitment the entry rate is quoted at.
B11: Absolute floor ($ per filing) | C11: 7 | D11: input | E11: Hard floor. No rate prints below this, at any band or commitment.
B12: Rounding increment ($) | C12: 0.1 | D12: input | E12: All rates round to the nearest $0.10.
B15: Volume bands
B16: Bands grow: first 25K, next 100K, next 250K, next 500K, then everything beyond.
B18: Band | C18: Lower bound | D18: Upper bound | E18: Band width | F18: Label
B19: 1 | C19: 0 | D19: 25000 | E19: =D19-C19 | F19: 0 to 25,000
B20: 2 | C20: 25000 | D20: 125000 | E20: =D20-C20 | F20: 25,001 to 125,000
B21: 3 | C21: 125000 | D21: 375000 | E21: =D21-C21 | F21: 125,001 to 375,000
B22: 4 | C22: 375000 | D22: 875000 | E22: =D22-C22 | F22: 375,001 to 875,000
B23: 5 | C23: 875000 | D23: 100000000 | E23: =D23-C23 | F23: 875,001+
E24: Upper bound of the final band is an arbitrary large number so the waterfall never truncates.
B26: Approval bands (discount off tier rate)
B27: Discount up to | C27: Approver
B28: 0 | C28: Standard rate card - no approval | E28: Bands per the memo: 0 / 15 / 25 / 50 / >50%.
B29: 0.15 | C29: AE / Sales lead
B30: 0.25 | C30: VP Sales
B31: 0.5 | C31: CRO
B32: 1 | C32: COO - off-framework

Sheet Rate Matrix
B2: DIY rate matrix
B3: Rows = volume band. Columns = minimum commitment. Every cell is a formula off Inputs.
B5: Volume band | C5: 10000 | D5: 20000 | E5: 30000 | F5: 40000 | G5: 50000 | H5: 60000 | I5: 70000 | J5: 80000 | K5: 90000 | L5: 100000
B6: =Inputs!F19 | C6: =MAX(Inputs!$C$11,ROUND((Inputs!$C$6+0*Inputs!$C$7)*(1-Inputs!$C$8)^((C$5-Inputs!$C$10)/Inputs!$C$9),1)) | D6: =MAX(Inputs!$C$11,ROUND((Inputs!$C$6+0*Inputs!$C$7)*(1-Inputs!$C$8)^((D$5-Inputs!$C$10)/Inputs!$C$9),1)) | E6: =MAX(Inputs!$C$11,ROUND((Inputs!$C$6+0*Inputs!$C$7)*(1-Inputs!$C$8)^((E$5-Inputs!$C$10)/Inputs!$C$9),1)) | F6: =MAX(Inputs!$C$11,ROUND((Inputs!$C$6+0*Inputs!$C$7)*(1-Inputs!$C$8)^((F$5-Inputs!$C$10)/Inputs!$C$9),1)) | G6: =MAX(Inputs!$C$11,ROUND((Inputs!$C$6+0*Inputs!$C$7)*(1-Inputs!$C$8)^((G$5-Inputs!$C$10)/Inputs!$C$9),1)) | H6: =MAX(Inputs!$C$11,ROUND((Inputs!$C$6+0*Inputs!$C$7)*(1-Inputs!$C$8)^((H$5-Inputs!$C$10)/Inputs!$C$9),1)) | I6: =MAX(Inputs!$C$11,ROUND((Inputs!$C$6+0*Inputs!$C$7)*(1-Inputs!$C$8)^((I$5-Inputs!$C$10)/Inputs!$C$9),1)) | J6: =MAX(Inputs!$C$11,ROUND((Inputs!$C$6+0*Inputs!$C$7)*(1-Inputs!$C$8)^((J$5-Inputs!$C$10)/Inputs!$C$9),1)) | ... L6: =MAX(Inputs!$C$11,ROUND((Inputs!$C$6+0*Inputs!$C$7)*(1-Inputs!$C$8)^((L$5-Inputs!$C$10)/Inputs!$C$9),1))
B7: =Inputs!F20 | C7: =MAX(Inputs!$C$11,ROUND((Inputs!$C$6+1*Inputs!$C$7)*(1-Inputs!$C$8)^((C$5-Inputs!$C$10)/Inputs!$C$9),1)) | D7: =MAX(Inputs!$C$11,ROUND((Inputs!$C$6+1*Inputs!$C$7)*(1-Inputs!$C$8)^((D$5-Inputs!$C$10)/Inputs!$C$9),1)) | E7: =MAX(Inputs!$C$11,ROUND((Inputs!$C$6+1*Inputs!$C$7)*(1-Inputs!$C$8)^((E$5-Inputs!$C$10)/Inputs!$C$9),1)) | F7: =MAX(Inputs!$C$11,ROUND((Inputs!$C$6+1*Inputs!$C$7)*(1-Inputs!$C$8)^((F$5-Inputs!$C$10)/Inputs!$C$9),1)) | G7: =MAX(Inputs!$C$11,ROUND((Inputs!$C$6+1*Inputs!$C$7)*(1-Inputs!$C$8)^((G$5-Inputs!$C$10)/Inputs!$C$9),1)) | H7: =MAX(Inputs!$C$11,ROUND((Inputs!$C$6+1*Inputs!$C$7)*(1-Inputs!$C$8)^((H$5-Inputs!$C$10)/Inputs!$C$9),1)) | I7: =MAX(Inputs!$C$11,ROUND((Inputs!$C$6+1*Inputs!$C$7)*(1-Inputs!$C$8)^((I$5-Inputs!$C$10)/Inputs!$C$9),1)) | J7: =MAX(Inputs!$C$11,ROUND((Inputs!$C$6+1*Inputs!$C$7)*(1-Inputs!$C$8)^((J$5-Inputs!$C$10)/Inputs!$C$9),1)) | ... L7: =MAX(Inputs!$C$11,ROUND((Inputs!$C$6+1*Inputs!$C$7)*(1-Inputs!$C$8)^((L$5-Inputs!$C$10)/Inputs!$C$9),1))
B8: =Inputs!F21 | C8: =MAX(Inputs!$C$11,ROUND((Inputs!$C$6+2*Inputs!$C$7)*(1-Inputs!$C$8)^((C$5-Inputs!$C$10)/Inputs!$C$9),1)) | D8: =MAX(Inputs!$C$11,ROUND((Inputs!$C$6+2*Inputs!$C$7)*(1-Inputs!$C$8)^((D$5-Inputs!$C$10)/Inputs!$C$9),1)) | E8: =MAX(Inputs!$C$11,ROUND((Inputs!$C$6+2*Inputs!$C$7)*(1-Inputs!$C$8)^((E$5-Inputs!$C$10)/Inputs!$C$9),1)) | F8: =MAX(Inputs!$C$11,ROUND((Inputs!$C$6+2*Inputs!$C$7)*(1-Inputs!$C$8)^((F$5-Inputs!$C$10)/Inputs!$C$9),1)) | G8: =MAX(Inputs!$C$11,ROUND((Inputs!$C$6+2*Inputs!$C$7)*(1-Inputs!$C$8)^((G$5-Inputs!$C$10)/Inputs!$C$9),1)) | H8: =MAX(Inputs!$C$11,ROUND((Inputs!$C$6+2*Inputs!$C$7)*(1-Inputs!$C$8)^((H$5-Inputs!$C$10)/Inputs!$C$9),1)) | I8: =MAX(Inputs!$C$11,ROUND((Inputs!$C$6+2*Inputs!$C$7)*(1-Inputs!$C$8)^((I$5-Inputs!$C$10)/Inputs!$C$9),1)) | J8: =MAX(Inputs!$C$11,ROUND((Inputs!$C$6+2*Inputs!$C$7)*(1-Inputs!$C$8)^((J$5-Inputs!$C$10)/Inputs!$C$9),1)) | ... L8: =MAX(Inputs!$C$11,ROUND((Inputs!$C$6+2*Inputs!$C$7)*(1-Inputs!$C$8)^((L$5-Inputs!$C$10)/Inputs!$C$9),1))
B9: =Inputs!F22 | C9: =MAX(Inputs!$C$11,ROUND((Inputs!$C$6+3*Inputs!$C$7)*(1-Inputs!$C$8)^((C$5-Inputs!$C$10)/Inputs!$C$9),1)) | D9: =MAX(Inputs!$C$11,ROUND((Inputs!$C$6+3*Inputs!$C$7)*(1-Inputs!$C$8)^((D$5-Inputs!$C$10)/Inputs!$C$9),1)) | E9: =MAX(Inputs!$C$11,ROUND((Inputs!$C$6+3*Inputs!$C$7)*(1-Inputs!$C$8)^((E$5-Inputs!$C$10)/Inputs!$C$9),1)) | F9: =MAX(Inputs!$C$11,ROUND((Inputs!$C$6+3*Inputs!$C$7)*(1-Inputs!$C$8)^((F$5-Inputs!$C$10)/Inputs!$C$9),1)) | G9: =MAX(Inputs!$C$11,ROUND((Inputs!$C$6+3*Inputs!$C$7)*(1-Inputs!$C$8)^((G$5-Inputs!$C$10)/Inputs!$C$9),1)) | H9: =MAX(Inputs!$C$11,ROUND((Inputs!$C$6+3*Inputs!$C$7)*(1-Inputs!$C$8)^((H$5-Inputs!$C$10)/Inputs!$C$9),1)) | I9: =MAX(Inputs!$C$11,ROUND((Inputs!$C$6+3*Inputs!$C$7)*(1-Inputs!$C$8)^((I$5-Inputs!$C$10)/Inputs!$C$9),1)) | J9: =MAX(Inputs!$C$11,ROUND((Inputs!$C$6+3*Inputs!$C$7)*(1-Inputs!$C$8)^((J$5-Inputs!$C$10)/Inputs!$C$9),1)) | ... L9: =MAX(Inputs!$C$11,ROUND((Inputs!$C$6+3*Inputs!$C$7)*(1-Inputs!$C$8)^((L$5-Inputs!$C$10)/Inputs!$C$9),1))
B10: =Inputs!F23 | C10: =MAX(Inputs!$C$11,ROUND((Inputs!$C$6+4*Inputs!$C$7)*(1-Inputs!$C$8)^((C$5-Inputs!$C$10)/Inputs!$C$9),1)) | D10: =MAX(Inputs!$C$11,ROUND((Inputs!$C$6+4*Inputs!$C$7)*(1-Inputs!$C$8)^((D$5-Inputs!$C$10)/Inputs!$C$9),1)) | E10: =MAX(Inputs!$C$11,ROUND((Inputs!$C$6+4*Inputs!$C$7)*(1-Inputs!$C$8)^((E$5-Inputs!$C$10)/Inputs!$C$9),1)) | F10: =MAX(Inputs!$C$11,ROUND((Inputs!$C$6+4*Inputs!$C$7)*(1-Inputs!$C$8)^((F$5-Inputs!$C$10)/Inputs!$C$9),1)) | G10: =MAX(Inputs!$C$11,ROUND((Inputs!$C$6+4*Inputs!$C$7)*(1-Inputs!$C$8)^((G$5-Inputs!$C$10)/Inputs!$C$9),1)) | H10: =MAX(Inputs!$C$11,ROUND((Inputs!$C$6+4*Inputs!$C$7)*(1-Inputs!$C$8)^((H$5-Inputs!$C$10)/Inputs!$C$9),1)) | I10: =MAX(Inputs!$C$11,ROUND((Inputs!$C$6+4*Inputs!$C$7)*(1-Inputs!$C$8)^((I$5-Inputs!$C$10)/Inputs!$C$9),1)) | J10: =MAX(Inputs!$C$11,ROUND((Inputs!$C$6+4*Inputs!$C$7)*(1-Inputs!$C$8)^((J$5-Inputs!$C$10)/Inputs!$C$9),1)) | ... L10: =MAX(Inputs!$C$11,ROUND((Inputs!$C$6+4*Inputs!$C$7)*(1-Inputs!$C$8)^((L$5-Inputs!$C$10)/Inputs!$C$9),1))
B13: Rates clamp at the floor and round to the nearest $0.10.
B14: Note: at the 0-25,000 band / 30K commitment the engine computes an exact $20.25 tie and rounds to $20.30; the memo's published matrix prints $20.20. Every other cell matches the memo exactly.

Sheet Deal Calculator
B2: Deal calculator
B3: Fill the yellow cells. Everything else calculates.
B5: Deal inputs
B6: Client name | C6: Example Fintech Co. | H6: Example row - overwrite with the real deal.
B7: Minimum unit commitment (filings) | C7: 50000 | H7: Drives the per-filing rate. Larger commitment = larger discount.
B8: Forecast annual volume (filings) | C8: 90000 | H8: Actual expected filings. Sweet spot is ~40% above the minimum in Year 1.
B9: Platform tier | C9: Growth | H9: Scale / Growth / Enterprise. Must match a tier name on Platform Tiers.
B10: Negotiated discount (% off rate) | C10: 0 | H10: Percentage off the tier rate. Campfire cannot bill dollar-step discounts.
B12: Billable volume
B13: Billable volume (filings) | C13: =MAX($C$8,$C$7) | H13: Volume below the committed minimum bills at the minimum.
B14: Volume vs minimum | C14: =IF($C$7=0,0,$C$8/$C$7-1) | H14: Positive = above the commitment. Negative triggers the renegotiation rule.
B15: Commitment status | C15: =IF($C$8<$C$7,"BELOW MINIMUM - renegotiate",IF(C14>=0.4,"Above sweet spot",IF(C14>=0.2,"In sweet spot","Above minimum")))
B17: Bill waterfall
B18: Volume is billed band by band at the rate for the chosen commitment.
B19: Volume band | C19: Lower | D19: Upper | E19: Filings in band | F19: Rate | G19: Band revenue
B20: =Inputs!F19 | C20: =Inputs!C19 | D20: =Inputs!D19 | E20: =MAX(0,MIN($C$13,D20)-C20) | F20: =MAX(Inputs!$C$11,ROUND((Inputs!$C$6+0*Inputs!$C$7)*(1-Inputs!$C$8)^(($C$7-Inputs!$C$10)/Inputs!$C$9),1)) | G20: =E20*F20
B21: =Inputs!F20 | C21: =Inputs!C20 | D21: =Inputs!D20 | E21: =MAX(0,MIN($C$13,D21)-C21) | F21: =MAX(Inputs!$C$11,ROUND((Inputs!$C$6+1*Inputs!$C$7)*(1-Inputs!$C$8)^(($C$7-Inputs!$C$10)/Inputs!$C$9),1)) | G21: =E21*F21
B22: =Inputs!F21 | C22: =Inputs!C21 | D22: =Inputs!D21 | E22: =MAX(0,MIN($C$13,D22)-C22) | F22: =MAX(Inputs!$C$11,ROUND((Inputs!$C$6+2*Inputs!$C$7)*(1-Inputs!$C$8)^(($C$7-Inputs!$C$10)/Inputs!$C$9),1)) | G22: =E22*F22
B23: =Inputs!F22 | C23: =Inputs!C22 | D23: =Inputs!D22 | E23: =MAX(0,MIN($C$13,D23)-C23) | F23: =MAX(Inputs!$C$11,ROUND((Inputs!$C$6+3*Inputs!$C$7)*(1-Inputs!$C$8)^(($C$7-Inputs!$C$10)/Inputs!$C$9),1)) | G23: =E23*F23
B24: =Inputs!F23 | C24: =Inputs!C23 | D24: =Inputs!D23 | E24: =MAX(0,MIN($C$13,D24)-C24) | F24: =MAX(Inputs!$C$11,ROUND((Inputs!$C$6+4*Inputs!$C$7)*(1-Inputs!$C$8)^(($C$7-Inputs!$C$10)/Inputs!$C$9),1)) | G24: =E24*F24
B25: Total | E25: =SUM(E20:E24) | G25: =SUM(G20:G24) | H25: Gross usage revenue before any negotiated discount.
B27: Contract value
B28: Gross usage revenue | C28: =G25 | H28: Sum of the waterfall.
B29: Negotiated discount | C29: =-G25*$C$10 | H29: Percentage off the tier rate.
B30: Net usage revenue | C30: =C28+C29
B31: Platform fee (annual) | C31: =INDEX('Platform Tiers'!$D$6:$D$8,MATCH($C$9,'Platform Tiers'!$B$6:$B$8,0)) | H31: From the selected tier.
B32: Total contract value (annual) | C32: =C30+C31 | H32: Usage plus platform fee.
B34: Effective economics
B35: Blended rate ($/filing) | C35: =IF($C$13=0,0,C30/$C$13) | H35: Net usage revenue divided by billable filings.
B36: All-in rate incl. platform fee | C36: =IF($C$13=0,0,C32/$C$13) | H36: What the client actually pays per filing.
B37: Headline band-1 rate | C37: =F20 | H37: The rate the deal is quoted at before the waterfall.
B38: Discount vs headline rate | C38: =IF(F20=0,0,C35/F20-1) | H38: How far the waterfall plus discount moves off the quoted rate.
B39: Floor check | C39: =IF(C35<Inputs!$C$11,"BELOW $7.00 FLOOR","OK") | H39: The floor binds per-band; this checks the blended outcome too.
B40: Approval required | C40: =INDEX(Inputs!$C$28:$C$32,MATCH(TRUE,INDEX(Inputs!$B$28:$B$32>=$C$10,0),0)) | H40: Driven by the negotiated discount.
B42: Reminder: this calculator is the DIY standard framework. Pro and Pro Review are bespoke - use this as a starting point, then negotiate.

Sheet Blended Rate Grid
B2: Effective blended rate by commitment and forecast volume
B3: $ per filing. Minimum commitment down the rows, forecast volume across. Blank = volume below the commitment (bills at the minimum).
B5: Commit \ Volume | C5: 25000 | D5: 50000 | E5: 100000 | F5: 250000 | G5: 500000 | H5: 1000000
B6: 10000 | C6: =IF(C$5<$B6,"",(MAX(0,MIN(C$5,Inputs!$D$19)-Inputs!$C$19)*MAX(Inputs!$C$11,ROUND((Inputs!$C$6+0*Inputs!$C$7)*(1-Inputs!$C$8)^(($B6-Inputs!$C$10)/Inputs!$C$9),1))+MAX(0,MIN(C$5,Inputs!$D$20)-Inputs!$C$20)*MAX(Inputs!$C$11,ROUND((Inputs!$C$6+1*Inputs!$C$7)*(1-Inputs!$C$8)^(($B6-Inputs!$C$10)/Inputs!$C$9),1))+MAX(0,MIN(C$5,Inputs!$D$21)-Inputs!$C$21)*MAX(Inputs!$C$11,ROUND((Inputs!$C$6+2*Inputs!$C$7)*(1-Inputs!$C$8)^(($B6-Inputs!$C$10)/Inputs!$C$9),1))+MAX(0,MIN(C$5,Inputs!$D$22)-Inputs!$C$22)*MAX(Inputs!$C$11,ROUND((Inputs!$C$6+3*Inputs!$C$7)*(1-Inputs!$C$8)^(($B6-Inputs!$C$10)/Inputs!$C$9),1))+MAX(0,MIN(C$5,Inputs!$D$23)-Inputs!$C$23)*MAX(Inputs!$C$11,ROUND((Inputs!$C$6+4*Inputs!$C$7)*(1-Inputs!$C$8)^(($B6-Inputs!$C$10)/Inputs!$C$9),1)))/C$5) | D6: =IF(D$5<$B6,"",(MAX(0,MIN(D$5,Inputs!$D$19)-Inputs!$C$19)*MAX(Inputs!$C$11,ROUND((Inputs!$C$6+0*Inputs!$C$7)*(1-Inputs!$C$8)^(($B6-Inputs!$C$10)/Inputs!$C$9),1))+MAX(0,MIN(D$5,Inputs!$D$20)-Inputs!$C$20)*MAX(Inputs!$C$11,ROUND((Inputs!$C$6+1*Inputs!$C$7)*(1-Inputs!$C$8)^(($B6-Inputs!$C$10)/Inputs!$C$9),1))+MAX(0,MIN(D$5,Inputs!$D$21)-Inputs!$C$21)*MAX(Inputs!$C$11,ROUND((Inputs!$C$6+2*Inputs!$C$7)*(1-Inputs!$C$8)^(($B6-Inputs!$C$10)/Inputs!$C$9),1))+MAX(0,MIN(D$5,Inputs!$D$22)-Inputs!$C$22)*MAX(Inputs!$C$11,ROUND((Inputs!$C$6+3*Inputs!$C$7)*(1-Inputs!$C$8)^(($B6-Inputs!$C$10)/Inputs!$C$9),1))+MAX(0,MIN(D$5,Inputs!$D$23)-Inputs!$C$23)*MAX(Inputs!$C$11,ROUND((Inputs!$C$6+4*Inputs!$C$7)*(1-Inputs!$C$8)^(($B6-Inputs!$C$10)/Inputs!$C$9),1)))/D$5) | E6: =IF(E$5<$B6,"",(MAX(0,MIN(E$5,Inputs!$D$19)-Inputs!$C$19)*MAX(Inputs!$C$11,ROUND((Inputs!$C$6+0*Inputs!$C$7)*(1-Inputs!$C$8)^(($B6-Inputs!$C$10)/Inputs!$C$9),1))+MAX(0,MIN(E$5,Inputs!$D$20)-Inputs!$C$20)*MAX(Inputs!$C$11,ROUND((Inputs!$C$6+1*Inputs!$C$7)*(1-Inputs!$C$8)^(($B6-Inputs!$C$10)/Inputs!$C$9),1))+MAX(0,MIN(E$5,Inputs!$D$21)-Inputs!$C$21)*MAX(Inputs!$C$11,ROUND((Inputs!$C$6+2*Inputs!$C$7)*(1-Inputs!$C$8)^(($B6-Inputs!$C$10)/Inputs!$C$9),1))+MAX(0,MIN(E$5,Inputs!$D$22)-Inputs!$C$22)*MAX(Inputs!$C$11,ROUND((Inputs!$C$6+3*Inputs!$C$7)*(1-Inputs!$C$8)^(($B6-Inputs!$C$10)/Inputs!$C$9),1))+MAX(0,MIN(E$5,Inputs!$D$23)-Inputs!$C$23)*MAX(Inputs!$C$11,ROUND((Inputs!$C$6+4*Inputs!$C$7)*(1-Inputs!$C$8)^(($B6-Inputs!$C$10)/Inputs!$C$9),1)))/E$5) | F6: =IF(F$5<$B6,"",(MAX(0,MIN(F$5,Inputs!$D$19)-Inputs!$C$19)*MAX(Inputs!$C$11,ROUND((Inputs!$C$6+0*Inputs!$C$7)*(1-Inputs!$C$8)^(($B6-Inputs!$C$10)/Inputs!$C$9),1))+MAX(0,MIN(F$5,Inputs!$D$20)-Inputs!$C$20)*MAX(Inputs!$C$11,ROUND((Inputs!$C$6+1*Inputs!$C$7)*(1-Inputs!$C$8)^(($B6-Inputs!$C$10)/Inputs!$C$9),1))+MAX(0,MIN(F$5,Inputs!$D$21)-Inputs!$C$21)*MAX(Inputs!$C$11,ROUND((Inputs!$C$6+2*Inputs!$C$7)*(1-Inputs!$C$8)^(($B6-Inputs!$C$10)/Inputs!$C$9),1))+MAX(0,MIN(F$5,Inputs!$D$22)-Inputs!$C$22)*MAX(Inputs!$C$11,ROUND((Inputs!$C$6+3*Inputs!$C$7)*(1-Inputs!$C$8)^(($B6-Inputs!$C$10)/Inputs!$C$9),1))+MAX(0,MIN(F$5,Inputs!$D$23)-Inputs!$C$23)*MAX(Inputs!$C$11,ROUND((Inputs!$C$6+4*Inputs!$C$7)*(1-Inputs!$C$8)^(($B6-Inputs!$C$10)/Inputs!$C$9),1)))/F$5) | G6: =IF(G$5<$B6,"",(MAX(0,MIN(G$5,Inputs!$D$19)-Inputs!$C$19)*MAX(Inputs!$C$11,ROUND((Inputs!$C$6+0*Inputs!$C$7)*(1-Inputs!$C$8)^(($B6-Inputs!$C$10)/Inputs!$C$9),1))+MAX(0,MIN(G$5,Inputs!$D$20)-Inputs!$C$20)*MAX(Inputs!$C$11,ROUND((Inputs!$C$6+1*Inputs!$C$7)*(1-Inputs!$C$8)^(($B6-Inputs!$C$10)/Inputs!$C$9),1))+MAX(0,MIN(G$5,Inputs!$D$21)-Inputs!$C$21)*MAX(Inputs!$C$11,ROUND((Inputs!$C$6+2*Inputs!$C$7)*(1-Inputs!$C$8)^(($B6-Inputs!$C$10)/Inputs!$C$9),1))+MAX(0,MIN(G$5,Inputs!$D$22)-Inputs!$C$22)*MAX(Inputs!$C$11,ROUND((Inputs!$C$6+3*Inputs!$C$7)*(1-Inputs!$C$8)^(($B6-Inputs!$C$10)/Inputs!$C$9),1))+MAX(0,MIN(G$5,Inputs!$D$23)-Inputs!$C$23)*MAX(Inputs!$C$11,ROUND((Inputs!$C$6+4*Inputs!$C$7)*(1-Inputs!$C$8)^(($B6-Inputs!$C$10)/Inputs!$C$9),1)))/G$5) | H6: =IF(H$5<$B6,"",(MAX(0,MIN(H$5,Inputs!$D$19)-Inputs!$C$19)*MAX(Inputs!$C$11,ROUND((Inputs!$C$6+0*Inputs!$C$7)*(1-Inputs!$C$8)^(($B6-Inputs!$C$10)/Inputs!$C$9),1))+MAX(0,MIN(H$5,Inputs!$D$20)-Inputs!$C$20)*MAX(Inputs!$C$11,ROUND((Inputs!$C$6+1*Inputs!$C$7)*(1-Inputs!$C$8)^(($B6-Inputs!$C$10)/Inputs!$C$9),1))+MAX(0,MIN(H$5,Inputs!$D$21)-Inputs!$C$21)*MAX(Inputs!$C$11,ROUND((Inputs!$C$6+2*Inputs!$C$7)*(1-Inputs!$C$8)^(($B6-Inputs!$C$10)/Inputs!$C$9),1))+MAX(0,MIN(H$5,Inputs!$D$22)-Inputs!$C$22)*MAX(Inputs!$C$11,ROUND((Inputs!$C$6+3*Inputs!$C$7)*(1-Inputs!$C$8)^(($B6-Inputs!$C$10)/Inputs!$C$9),1))+MAX(0,MIN(H$5,Inputs!$D$23)-Inputs!$C$23)*MAX(Inputs!$C$11,ROUND((Inputs!$C$6+4*Inputs!$C$7)*(1-Inputs!$C$8)^(($B6-Inputs!$C$10)/Inputs!$C$9),1)))/H$5)
B7: 20000 | C7: =IF(C$5<$B7,"",(MAX(0,MIN(C$5,Inputs!$D$19)-Inputs!$C$19)*MAX(Inputs!$C$11,ROUND((Inputs!$C$6+0*Inputs!$C$7)*(1-Inputs!$C$8)^(($B7-Inputs!$C$10)/Inputs!$C$9),1))+MAX(0,MIN(C$5,Inputs!$D$20)-Inputs!$C$20)*MAX(Inputs!$C$11,ROUND((Inputs!$C$6+1*Inputs!$C$7)*(1-Inputs!$C$8)^(($B7-Inputs!$C$10)/Inputs!$C$9),1))+MAX(0,MIN(C$5,Inputs!$D$21)-Inputs!$C$21)*MAX(Inputs!$C$11,ROUND((Inputs!$C$6+2*Inputs!$C$7)*(1-Inputs!$C$8)^(($B7-Inputs!$C$10)/Inputs!$C$9),1))+MAX(0,MIN(C$5,Inputs!$D$22)-Inputs!$C$22)*MAX(Inputs!$C$11,ROUND((Inputs!$C$6+3*Inputs!$C$7)*(1-Inputs!$C$8)^(($B7-Inputs!$C$10)/Inputs!$C$9),1))+MAX(0,MIN(C$5,Inputs!$D$23)-Inputs!$C$23)*MAX(Inputs!$C$11,ROUND((Inputs!$C$6+4*Inputs!$C$7)*(1-Inputs!$C$8)^(($B7-Inputs!$C$10)/Inputs!$C$9),1)))/C$5) | D7: =IF(D$5<$B7,"",(MAX(0,MIN(D$5,Inputs!$D$19)-Inputs!$C$19)*MAX(Inputs!$C$11,ROUND((Inputs!$C$6+0*Inputs!$C$7)*(1-Inputs!$C$8)^(($B7-Inputs!$C$10)/Inputs!$C$9),1))+MAX(0,MIN(D$5,Inputs!$D$20)-Inputs!$C$20)*MAX(Inputs!$C$11,ROUND((Inputs!$C$6+1*Inputs!$C$7)*(1-Inputs!$C$8)^(($B7-Inputs!$C$10)/Inputs!$C$9),1))+MAX(0,MIN(D$5,Inputs!$D$21)-Inputs!$C$21)*MAX(Inputs!$C$11,ROUND((Inputs!$C$6+2*Inputs!$C$7)*(1-Inputs!$C$8)^(($B7-Inputs!$C$10)/Inputs!$C$9),1))+MAX(0,MIN(D$5,Inputs!$D$22)-Inputs!$C$22)*MAX(Inputs!$C$11,ROUND((Inputs!$C$6+3*Inputs!$C$7)*(1-Inputs!$C$8)^(($B7-Inputs!$C$10)/Inputs!$C$9),1))+MAX(0,MIN(D$5,Inputs!$D$23)-Inputs!$C$23)*MAX(Inputs!$C$11,ROUND((Inputs!$C$6+4*Inputs!$C$7)*(1-Inputs!$C$8)^(($B7-Inputs!$C$10)/Inputs!$C$9),1)))/D$5) | E7: =IF(E$5<$B7,"",(MAX(0,MIN(E$5,Inputs!$D$19)-Inputs!$C$19)*MAX(Inputs!$C$11,ROUND((Inputs!$C$6+0*Inputs!$C$7)*(1-Inputs!$C$8)^(($B7-Inputs!$C$10)/Inputs!$C$9),1))+MAX(0,MIN(E$5,Inputs!$D$20)-Inputs!$C$20)*MAX(Inputs!$C$11,ROUND((Inputs!$C$6+1*Inputs!$C$7)*(1-Inputs!$C$8)^(($B7-Inputs!$C$10)/Inputs!$C$9),1))+MAX(0,MIN(E$5,Inputs!$D$21)-Inputs!$C$21)*MAX(Inputs!$C$11,ROUND((Inputs!$C$6+2*Inputs!$C$7)*(1-Inputs!$C$8)^(($B7-Inputs!$C$10)/Inputs!$C$9),1))+MAX(0,MIN(E$5,Inputs!$D$22)-Inputs!$C$22)*MAX(Inputs!$C$11,ROUND((Inputs!$C$6+3*Inputs!$C$7)*(1-Inputs!$C$8)^(($B7-Inputs!$C$10)/Inputs!$C$9),1))+MAX(0,MIN(E$5,Inputs!$D$23)-Inputs!$C$23)*MAX(Inputs!$C$11,ROUND((Inputs!$C$6+4*Inputs!$C$7)*(1-Inputs!$C$8)^(($B7-Inputs!$C$10)/Inputs!$C$9),1)))/E$5) | F7: =IF(F$5<$B7,"",(MAX(0,MIN(F$5,Inputs!$D$19)-Inputs!$C$19)*MAX(Inputs!$C$11,ROUND((Inputs!$C$6+0*Inputs!$C$7)*(1-Inputs!$C$8)^(($B7-Inputs!$C$10)/Inputs!$C$9),1))+MAX(0,MIN(F$5,Inputs!$D$20)-Inputs!$C$20)*MAX(Inputs!$C$11,ROUND((Inputs!$C$6+1*Inputs!$C$7)*(1-Inputs!$C$8)^(($B7-Inputs!$C$10)/Inputs!$C$9),1))+MAX(0,MIN(F$5,Inputs!$D$21)-Inputs!$C$21)*MAX(Inputs!$C$11,ROUND((Inputs!$C$6+2*Inputs!$C$7)*(1-Inputs!$C$8)^(($B7-Inputs!$C$10)/Inputs!$C$9),1))+MAX(0,MIN(F$5,Inputs!$D$22)-Inputs!$C$22)*MAX(Inputs!$C$11,ROUND((Inputs!$C$6+3*Inputs!$C$7)*(1-Inputs!$C$8)^(($B7-Inputs!$C$10)/Inputs!$C$9),1))+MAX(0,MIN(F$5,Inputs!$D$23)-Inputs!$C$23)*MAX(Inputs!$C$11,ROUND((Inputs!$C$6+4*Inputs!$C$7)*(1-Inputs!$C$8)^(($B7-Inputs!$C$10)/Inputs!$C$9),1)))/F$5) | G7: =IF(G$5<$B7,"",(MAX(0,MIN(G$5,Inputs!$D$19)-Inputs!$C$19)*MAX(Inputs!$C$11,ROUND((Inputs!$C$6+0*Inputs!$C$7)*(1-Inputs!$C$8)^(($B7-Inputs!$C$10)/Inputs!$C$9),1))+MAX(0,MIN(G$5,Inputs!$D$20)-Inputs!$C$20)*MAX(Inputs!$C$11,ROUND((Inputs!$C$6+1*Inputs!$C$7)*(1-Inputs!$C$8)^(($B7-Inputs!$C$10)/Inputs!$C$9),1))+MAX(0,MIN(G$5,Inputs!$D$21)-Inputs!$C$21)*MAX(Inputs!$C$11,ROUND((Inputs!$C$6+2*Inputs!$C$7)*(1-Inputs!$C$8)^(($B7-Inputs!$C$10)/Inputs!$C$9),1))+MAX(0,MIN(G$5,Inputs!$D$22)-Inputs!$C$22)*MAX(Inputs!$C$11,ROUND((Inputs!$C$6+3*Inputs!$C$7)*(1-Inputs!$C$8)^(($B7-Inputs!$C$10)/Inputs!$C$9),1))+MAX(0,MIN(G$5,Inputs!$D$23)-Inputs!$C$23)*MAX(Inputs!$C$11,ROUND((Inputs!$C$6+4*Inputs!$C$7)*(1-Inputs!$C$8)^(($B7-Inputs!$C$10)/Inputs!$C$9),1)))/G$5) | H7: =IF(H$5<$B7,"",(MAX(0,MIN(H$5,Inputs!$D$19)-Inputs!$C$19)*MAX(Inputs!$C$11,ROUND((Inputs!$C$6+0*Inputs!$C$7)*(1-Inputs!$C$8)^(($B7-Inputs!$C$10)/Inputs!$C$9),1))+MAX(0,MIN(H$5,Inputs!$D$20)-Inputs!$C$20)*MAX(Inputs!$C$11,ROUND((Inputs!$C$6+1*Inputs!$C$7)*(1-Inputs!$C$8)^(($B7-Inputs!$C$10)/Inputs!$C$9),1))+MAX(0,MIN(H$5,Inputs!$D$21)-Inputs!$C$21)*MAX(Inputs!$C$11,ROUND((Inputs!$C$6+2*Inputs!$C$7)*(1-Inputs!$C$8)^(($B7-Inputs!$C$10)/Inputs!$C$9),1))+MAX(0,MIN(H$5,Inputs!$D$22)-Inputs!$C$22)*MAX(Inputs!$C$11,ROUND((Inputs!$C$6+3*Inputs!$C$7)*(1-Inputs!$C$8)^(($B7-Inputs!$C$10)/Inputs!$C$9),1))+MAX(0,MIN(H$5,Inputs!$D$23)-Inputs!$C$23)*MAX(Inputs!$C$11,ROUND((Inputs!$C$6+4*Inputs!$C$7)*(1-Inputs!$C$8)^(($B7-Inputs!$C$10)/Inputs!$C$9),1)))/H$5)
B8: 30000 | C8: =IF(C$5<$B8,"",(MAX(0,MIN(C$5,Inputs!$D$19)-Inputs!$C$19)*MAX(Inputs!$C$11,ROUND((Inputs!$C$6+0*Inputs!$C$7)*(1-Inputs!$C$8)^(($B8-Inputs!$C$10)/Inputs!$C$9),1))+MAX(0,MIN(C$5,Inputs!$D$20)-Inputs!$C$20)*MAX(Inputs!$C$11,ROUND((Inputs!$C$6+1*Inputs!$C$7)*(1-Inputs!$C$8)^(($B8-Inputs!$C$10)/Inputs!$C$9),1))+MAX(0,MIN(C$5,Inputs!$D$21)-Inputs!$C$21)*MAX(Inputs!$C$11,ROUND((Inputs!$C$6+2*Inputs!$C$7)*(1-Inputs!$C$8)^(($B8-Inputs!$C$10)/Inputs!$C$9),1))+MAX(0,MIN(C$5,Inputs!$D$22)-Inputs!$C$22)*MAX(Inputs!$C$11,ROUND((Inputs!$C$6+3*Inputs!$C$7)*(1-Inputs!$C$8)^(($B8-Inputs!$C$10)/Inputs!$C$9),1))+MAX(0,MIN(C$5,Inputs!$D$23)-Inputs!$C$23)*MAX(Inputs!$C$11,ROUND((Inputs!$C$6+4*Inputs!$C$7)*(1-Inputs!$C$8)^(($B8-Inputs!$C$10)/Inputs!$C$9),1)))/C$5) | D8: =IF(D$5<$B8,"",(MAX(0,MIN(D$5,Inputs!$D$19)-Inputs!$C$19)*MAX(Inputs!$C$11,ROUND((Inputs!$C$6+0*Inputs!$C$7)*(1-Inputs!$C$8)^(($B8-Inputs!$C$10)/Inputs!$C$9),1))+MAX(0,MIN(D$5,Inputs!$D$20)-Inputs!$C$20)*MAX(Inputs!$C$11,ROUND((Inputs!$C$6+1*Inputs!$C$7)*(1-Inputs!$C$8)^(($B8-Inputs!$C$10)/Inputs!$C$9),1))+MAX(0,MIN(D$5,Inputs!$D$21)-Inputs!$C$21)*MAX(Inputs!$C$11,ROUND((Inputs!$C$6+2*Inputs!$C$7)*(1-Inputs!$C$8)^(($B8-Inputs!$C$10)/Inputs!$C$9),1))+MAX(0,MIN(D$5,Inputs!$D$22)-Inputs!$C$22)*MAX(Inputs!$C$11,ROUND((Inputs!$C$6+3*Inputs!$C$7)*(1-Inputs!$C$8)^(($B8-Inputs!$C$10)/Inputs!$C$9),1))+MAX(0,MIN(D$5,Inputs!$D$23)-Inputs!$C$23)*MAX(Inputs!$C$11,ROUND((Inputs!$C$6+4*Inputs!$C$7)*(1-Inputs!$C$8)^(($B8-Inputs!$C$10)/Inputs!$C$9),1)))/D$5) | E8: =IF(E$5<$B8,"",(MAX(0,MIN(E$5,Inputs!$D$19)-Inputs!$C$19)*MAX(Inputs!$C$11,ROUND((Inputs!$C$6+0*Inputs!$C$7)*(1-Inputs!$C$8)^(($B8-Inputs!$C$10)/Inputs!$C$9),1))+MAX(0,MIN(E$5,Inputs!$D$20)-Inputs!$C$20)*MAX(Inputs!$C$11,ROUND((Inputs!$C$6+1*Inputs!$C$7)*(1-Inputs!$C$8)^(($B8-Inputs!$C$10)/Inputs!$C$9),1))+MAX(0,MIN(E$5,Inputs!$D$21)-Inputs!$C$21)*MAX(Inputs!$C$11,ROUND((Inputs!$C$6+2*Inputs!$C$7)*(1-Inputs!$C$8)^(($B8-Inputs!$C$10)/Inputs!$C$9),1))+MAX(0,MIN(E$5,Inputs!$D$22)-Inputs!$C$22)*MAX(Inputs!$C$11,ROUND((Inputs!$C$6+3*Inputs!$C$7)*(1-Inputs!$C$8)^(($B8-Inputs!$C$10)/Inputs!$C$9),1))+MAX(0,MIN(E$5,Inputs!$D$23)-Inputs!$C$23)*MAX(Inputs!$C$11,ROUND((Inputs!$C$6+4*Inputs!$C$7)*(1-Inputs!$C$8)^(($B8-Inputs!$C$10)/Inputs!$C$9),1)))/E$5) | F8: =IF(F$5<$B8,"",(MAX(0,MIN(F$5,Inputs!$D$19)-Inputs!$C$19)*MAX(Inputs!$C$11,ROUND((Inputs!$C$6+0*Inputs!$C$7)*(1-Inputs!$C$8)^(($B8-Inputs!$C$10)/Inputs!$C$9),1))+MAX(0,MIN(F$5,Inputs!$D$20)-Inputs!$C$20)*MAX(Inputs!$C$11,ROUND((Inputs!$C$6+1*Inputs!$C$7)*(1-Inputs!$C$8)^(($B8-Inputs!$C$10)/Inputs!$C$9),1))+MAX(0,MIN(F$5,Inputs!$D$21)-Inputs!$C$21)*MAX(Inputs!$C$11,ROUND((Inputs!$C$6+2*Inputs!$C$7)*(1-Inputs!$C$8)^(($B8-Inputs!$C$10)/Inputs!$C$9),1))+MAX(0,MIN(F$5,Inputs!$D$22)-Inputs!$C$22)*MAX(Inputs!$C$11,ROUND((Inputs!$C$6+3*Inputs!$C$7)*(1-Inputs!$C$8)^(($B8-Inputs!$C$10)/Inputs!$C$9),1))+MAX(0,MIN(F$5,Inputs!$D$23)-Inputs!$C$23)*MAX(Inputs!$C$11,ROUND((Inputs!$C$6+4*Inputs!$C$7)*(1-Inputs!$C$8)^(($B8-Inputs!$C$10)/Inputs!$C$9),1)))/F$5) | G8: =IF(G$5<$B8,"",(MAX(0,MIN(G$5,Inputs!$D$19)-Inputs!$C$19)*MAX(Inputs!$C$11,ROUND((Inputs!$C$6+0*Inputs!$C$7)*(1-Inputs!$C$8)^(($B8-Inputs!$C$10)/Inputs!$C$9),1))+MAX(0,MIN(G$5,Inputs!$D$20)-Inputs!$C$20)*MAX(Inputs!$C$11,ROUND((Inputs!$C$6+1*Inputs!$C$7)*(1-Inputs!$C$8)^(($B8-Inputs!$C$10)/Inputs!$C$9),1))+MAX(0,MIN(G$5,Inputs!$D$21)-Inputs!$C$21)*MAX(Inputs!$C$11,ROUND((Inputs!$C$6+2*Inputs!$C$7)*(1-Inputs!$C$8)^(($B8-Inputs!$C$10)/Inputs!$C$9),1))+MAX(0,MIN(G$5,Inputs!$D$22)-Inputs!$C$22)*MAX(Inputs!$C$11,ROUND((Inputs!$C$6+3*Inputs!$C$7)*(1-Inputs!$C$8)^(($B8-Inputs!$C$10)/Inputs!$C$9),1))+MAX(0,MIN(G$5,Inputs!$D$23)-Inputs!$C$23)*MAX(Inputs!$C$11,ROUND((Inputs!$C$6+4*Inputs!$C$7)*(1-Inputs!$C$8)^(($B8-Inputs!$C$10)/Inputs!$C$9),1)))/G$5) | H8: =IF(H$5<$B8,"",(MAX(0,MIN(H$5,Inputs!$D$19)-Inputs!$C$19)*MAX(Inputs!$C$11,ROUND((Inputs!$C$6+0*Inputs!$C$7)*(1-Inputs!$C$8)^(($B8-Inputs!$C$10)/Inputs!$C$9),1))+MAX(0,MIN(H$5,Inputs!$D$20)-Inputs!$C$20)*MAX(Inputs!$C$11,ROUND((Inputs!$C$6+1*Inputs!$C$7)*(1-Inputs!$C$8)^(($B8-Inputs!$C$10)/Inputs!$C$9),1))+MAX(0,MIN(H$5,Inputs!$D$21)-Inputs!$C$21)*MAX(Inputs!$C$11,ROUND((Inputs!$C$6+2*Inputs!$C$7)*(1-Inputs!$C$8)^(($B8-Inputs!$C$10)/Inputs!$C$9),1))+MAX(0,MIN(H$5,Inputs!$D$22)-Inputs!$C$22)*MAX(Inputs!$C$11,ROUND((Inputs!$C$6+3*Inputs!$C$7)*(1-Inputs!$C$8)^(($B8-Inputs!$C$10)/Inputs!$C$9),1))+MAX(0,MIN(H$5,Inputs!$D$23)-Inputs!$C$23)*MAX(Inputs!$C$11,ROUND((Inputs!$C$6+4*Inputs!$C$7)*(1-Inputs!$C$8)^(($B8-Inputs!$C$10)/Inputs!$C$9),1)))/H$5)
B9: 40000 | C9: =IF(C$5<$B9,"",(MAX(0,MIN(C$5,Inputs!$D$19)-Inputs!$C$19)*MAX(Inputs!$C$11,ROUND((Inputs!$C$6+0*Inputs!$C$7)*(1-Inputs!$C$8)^(($B9-Inputs!$C$10)/Inputs!$C$9),1))+MAX(0,MIN(C$5,Inputs!$D$20)-Inputs!$C$20)*MAX(Inputs!$C$11,ROUND((Inputs!$C$6+1*Inputs!$C$7)*(1-Inputs!$C$8)^(($B9-Inputs!$C$10)/Inputs!$C$9),1))+MAX(0,MIN(C$5,Inputs!$D$21)-Inputs!$C$21)*MAX(Inputs!$C$11,ROUND((Inputs!$C$6+2*Inputs!$C$7)*(1-Inputs!$C$8)^(($B9-Inputs!$C$10)/Inputs!$C$9),1))+MAX(0,MIN(C$5,Inputs!$D$22)-Inputs!$C$22)*MAX(Inputs!$C$11,ROUND((Inputs!$C$6+3*Inputs!$C$7)*(1-Inputs!$C$8)^(($B9-Inputs!$C$10)/Inputs!$C$9),1))+MAX(0,MIN(C$5,Inputs!$D$23)-Inputs!$C$23)*MAX(Inputs!$C$11,ROUND((Inputs!$C$6+4*Inputs!$C$7)*(1-Inputs!$C$8)^(($B9-Inputs!$C$10)/Inputs!$C$9),1)))/C$5) | D9: =IF(D$5<$B9,"",(MAX(0,MIN(D$5,Inputs!$D$19)-Inputs!$C$19)*MAX(Inputs!$C$11,ROUND((Inputs!$C$6+0*Inputs!$C$7)*(1-Inputs!$C$8)^(($B9-Inputs!$C$10)/Inputs!$C$9),1))+MAX(0,MIN(D$5,Inputs!$D$20)-Inputs!$C$20)*MAX(Inputs!$C$11,ROUND((Inputs!$C$6+1*Inputs!$C$7)*(1-Inputs!$C$8)^(($B9-Inputs!$C$10)/Inputs!$C$9),1))+MAX(0,MIN(D$5,Inputs!$D$21)-Inputs!$C$21)*MAX(Inputs!$C$11,ROUND((Inputs!$C$6+2*Inputs!$C$7)*(1-Inputs!$C$8)^(($B9-Inputs!$C$10)/Inputs!$C$9),1))+MAX(0,MIN(D$5,Inputs!$D$22)-Inputs!$C$22)*MAX(Inputs!$C$11,ROUND((Inputs!$C$6+3*Inputs!$C$7)*(1-Inputs!$C$8)^(($B9-Inputs!$C$10)/Inputs!$C$9),1))+MAX(0,MIN(D$5,Inputs!$D$23)-Inputs!$C$23)*MAX(Inputs!$C$11,ROUND((Inputs!$C$6+4*Inputs!$C$7)*(1-Inputs!$C$8)^(($B9-Inputs!$C$10)/Inputs!$C$9),1)))/D$5) | E9: =IF(E$5<$B9,"",(MAX(0,MIN(E$5,Inputs!$D$19)-Inputs!$C$19)*MAX(Inputs!$C$11,ROUND((Inputs!$C$6+0*Inputs!$C$7)*(1-Inputs!$C$8)^(($B9-Inputs!$C$10)/Inputs!$C$9),1))+MAX(0,MIN(E$5,Inputs!$D$20)-Inputs!$C$20)*MAX(Inputs!$C$11,ROUND((Inputs!$C$6+1*Inputs!$C$7)*(1-Inputs!$C$8)^(($B9-Inputs!$C$10)/Inputs!$C$9),1))+MAX(0,MIN(E$5,Inputs!$D$21)-Inputs!$C$21)*MAX(Inputs!$C$11,ROUND((Inputs!$C$6+2*Inputs!$C$7)*(1-Inputs!$C$8)^(($B9-Inputs!$C$10)/Inputs!$C$9),1))+MAX(0,MIN(E$5,Inputs!$D$22)-Inputs!$C$22)*MAX(Inputs!$C$11,ROUND((Inputs!$C$6+3*Inputs!$C$7)*(1-Inputs!$C$8)^(($B9-Inputs!$C$10)/Inputs!$C$9),1))+MAX(0,MIN(E$5,Inputs!$D$23)-Inputs!$C$23)*MAX(Inputs!$C$11,ROUND((Inputs!$C$6+4*Inputs!$C$7)*(1-Inputs!$C$8)^(($B9-Inputs!$C$10)/Inputs!$C$9),1)))/E$5) | F9: =IF(F$5<$B9,"",(MAX(0,MIN(F$5,Inputs!$D$19)-Inputs!$C$19)*MAX(Inputs!$C$11,ROUND((Inputs!$C$6+0*Inputs!$C$7)*(1-Inputs!$C$8)^(($B9-Inputs!$C$10)/Inputs!$C$9),1))+MAX(0,MIN(F$5,Inputs!$D$20)-Inputs!$C$20)*MAX(Inputs!$C$11,ROUND((Inputs!$C$6+1*Inputs!$C$7)*(1-Inputs!$C$8)^(($B9-Inputs!$C$10)/Inputs!$C$9),1))+MAX(0,MIN(F$5,Inputs!$D$21)-Inputs!$C$21)*MAX(Inputs!$C$11,ROUND((Inputs!$C$6+2*Inputs!$C$7)*(1-Inputs!$C$8)^(($B9-Inputs!$C$10)/Inputs!$C$9),1))+MAX(0,MIN(F$5,Inputs!$D$22)-Inputs!$C$22)*MAX(Inputs!$C$11,ROUND((Inputs!$C$6+3*Inputs!$C$7)*(1-Inputs!$C$8)^(($B9-Inputs!$C$10)/Inputs!$C$9),1))+MAX(0,MIN(F$5,Inputs!$D$23)-Inputs!$C$23)*MAX(Inputs!$C$11,ROUND((Inputs!$C$6+4*Inputs!$C$7)*(1-Inputs!$C$8)^(($B9-Inputs!$C$10)/Inputs!$C$9),1)))/F$5) | G9: =IF(G$5<$B9,"",(MAX(0,MIN(G$5,Inputs!$D$19)-Inputs!$C$19)*MAX(Inputs!$C$11,ROUND((Inputs!$C$6+0*Inputs!$C$7)*(1-Inputs!$C$8)^(($B9-Inputs!$C$10)/Inputs!$C$9),1))+MAX(0,MIN(G$5,Inputs!$D$20)-Inputs!$C$20)*MAX(Inputs!$C$11,ROUND((Inputs!$C$6+1*Inputs!$C$7)*(1-Inputs!$C$8)^(($B9-Inputs!$C$10)/Inputs!$C$9),1))+MAX(0,MIN(G$5,Inputs!$D$21)-Inputs!$C$21)*MAX(Inputs!$C$11,ROUND((Inputs!$C$6+2*Inputs!$C$7)*(1-Inputs!$C$8)^(($B9-Inputs!$C$10)/Inputs!$C$9),1))+MAX(0,MIN(G$5,Inputs!$D$22)-Inputs!$C$22)*MAX(Inputs!$C$11,ROUND((Inputs!$C$6+3*Inputs!$C$7)*(1-Inputs!$C$8)^(($B9-Inputs!$C$10)/Inputs!$C$9),1))+MAX(0,MIN(G$5,Inputs!$D$23)-Inputs!$C$23)*MAX(Inputs!$C$11,ROUND((Inputs!$C$6+4*Inputs!$C$7)*(1-Inputs!$C$8)^(($B9-Inputs!$C$10)/Inputs!$C$9),1)))/G$5) | H9: =IF(H$5<$B9,"",(MAX(0,MIN(H$5,Inputs!$D$19)-Inputs!$C$19)*MAX(Inputs!$C$11,ROUND((Inputs!$C$6+0*Inputs!$C$7)*(1-Inputs!$C$8)^(($B9-Inputs!$C$10)/Inputs!$C$9),1))+MAX(0,MIN(H$5,Inputs!$D$20)-Inputs!$C$20)*MAX(Inputs!$C$11,ROUND((Inputs!$C$6+1*Inputs!$C$7)*(1-Inputs!$C$8)^(($B9-Inputs!$C$10)/Inputs!$C$9),1))+MAX(0,MIN(H$5,Inputs!$D$21)-Inputs!$C$21)*MAX(Inputs!$C$11,ROUND((Inputs!$C$6+2*Inputs!$C$7)*(1-Inputs!$C$8)^(($B9-Inputs!$C$10)/Inputs!$C$9),1))+MAX(0,MIN(H$5,Inputs!$D$22)-Inputs!$C$22)*MAX(Inputs!$C$11,ROUND((Inputs!$C$6+3*Inputs!$C$7)*(1-Inputs!$C$8)^(($B9-Inputs!$C$10)/Inputs!$C$9),1))+MAX(0,MIN(H$5,Inputs!$D$23)-Inputs!$C$23)*MAX(Inputs!$C$11,ROUND((Inputs!$C$6+4*Inputs!$C$7)*(1-Inputs!$C$8)^(($B9-Inputs!$C$10)/Inputs!$C$9),1)))/H$5)
B10: 50000 | C10: =IF(C$5<$B10,"",(MAX(0,MIN(C$5,Inputs!$D$19)-Inputs!$C$19)*MAX(Inputs!$C$11,ROUND((Inputs!$C$6+0*Inputs!$C$7)*(1-Inputs!$C$8)^(($B10-Inputs!$C$10)/Inputs!$C$9),1))+MAX(0,MIN(C$5,Inputs!$D$20)-Inputs!$C$20)*MAX(Inputs!$C$11,ROUND((Inputs!$C$6+1*Inputs!$C$7)*(1-Inputs!$C$8)^(($B10-Inputs!$C$10)/Inputs!$C$9),1))+MAX(0,MIN(C$5,Inputs!$D$21)-Inputs!$C$21)*MAX(Inputs!$C$11,ROUND((Inputs!$C$6+2*Inputs!$C$7)*(1-Inputs!$C$8)^(($B10-Inputs!$C$10)/Inputs!$C$9),1))+MAX(0,MIN(C$5,Inputs!$D$22)-Inputs!$C$22)*MAX(Inputs!$C$11,ROUND((Inputs!$C$6+3*Inputs!$C$7)*(1-Inputs!$C$8)^(($B10-Inputs!$C$10)/Inputs!$C$9),1))+MAX(0,MIN(C$5,Inputs!$D$23)-Inputs!$C$23)*MAX(Inputs!$C$11,ROUND((Inputs!$C$6+4*Inputs!$C$7)*(1-Inputs!$C$8)^(($B10-Inputs!$C$10)/Inputs!$C$9),1)))/C$5) | D10: =IF(D$5<$B10,"",(MAX(0,MIN(D$5,Inputs!$D$19)-Inputs!$C$19)*MAX(Inputs!$C$11,ROUND((Inputs!$C$6+0*Inputs!$C$7)*(1-Inputs!$C$8)^(($B10-Inputs!$C$10)/Inputs!$C$9),1))+MAX(0,MIN(D$5,Inputs!$D$20)-Inputs!$C$20)*MAX(Inputs!$C$11,ROUND((Inputs!$C$6+1*Inputs!$C$7)*(1-Inputs!$C$8)^(($B10-Inputs!$C$10)/Inputs!$C$9),1))+MAX(0,MIN(D$5,Inputs!$D$21)-Inputs!$C$21)*MAX(Inputs!$C$11,ROUND((Inputs!$C$6+2*Inputs!$C$7)*(1-Inputs!$C$8)^(($B10-Inputs!$C$10)/Inputs!$C$9),1))+MAX(0,MIN(D$5,Inputs!$D$22)-Inputs!$C$22)*MAX(Inputs!$C$11,ROUND((Inputs!$C$6+3*Inputs!$C$7)*(1-Inputs!$C$8)^(($B10-Inputs!$C$10)/Inputs!$C$9),1))+MAX(0,MIN(D$5,Inputs!$D$23)-Inputs!$C$23)*MAX(Inputs!$C$11,ROUND((Inputs!$C$6+4*Inputs!$C$7)*(1-Inputs!$C$8)^(($B10-Inputs!$C$10)/Inputs!$C$9),1)))/D$5) | E10: =IF(E$5<$B10,"",(MAX(0,MIN(E$5,Inputs!$D$19)-Inputs!$C$19)*MAX(Inputs!$C$11,ROUND((Inputs!$C$6+0*Inputs!$C$7)*(1-Inputs!$C$8)^(($B10-Inputs!$C$10)/Inputs!$C$9),1))+MAX(0,MIN(E$5,Inputs!$D$20)-Inputs!$C$20)*MAX(Inputs!$C$11,ROUND((Inputs!$C$6+1*Inputs!$C$7)*(1-Inputs!$C$8)^(($B10-Inputs!$C$10)/Inputs!$C$9),1))+MAX(0,MIN(E$5,Inputs!$D$21)-Inputs!$C$21)*MAX(Inputs!$C$11,ROUND((Inputs!$C$6+2*Inputs!$C$7)*(1-Inputs!$C$8)^(($B10-Inputs!$C$10)/Inputs!$C$9),1))+MAX(0,MIN(E$5,Inputs!$D$22)-Inputs!$C$22)*MAX(Inputs!$C$11,ROUND((Inputs!$C$6+3*Inputs!$C$7)*(1-Inputs!$C$8)^(($B10-Inputs!$C$10)/Inputs!$C$9),1))+MAX(0,MIN(E$5,Inputs!$D$23)-Inputs!$C$23)*MAX(Inputs!$C$11,ROUND((Inputs!$C$6+4*Inputs!$C$7)*(1-Inputs!$C$8)^(($B10-Inputs!$C$10)/Inputs!$C$9),1)))/E$5) | F10: =IF(F$5<$B10,"",(MAX(0,MIN(F$5,Inputs!$D$19)-Inputs!$C$19)*MAX(Inputs!$C$11,ROUND((Inputs!$C$6+0*Inputs!$C$7)*(1-Inputs!$C$8)^(($B10-Inputs!$C$10)/Inputs!$C$9),1))+MAX(0,MIN(F$5,Inputs!$D$20)-Inputs!$C$20)*MAX(Inputs!$C$11,ROUND((Inputs!$C$6+1*Inputs!$C$7)*(1-Inputs!$C$8)^(($B10-Inputs!$C$10)/Inputs!$C$9),1))+MAX(0,MIN(F$5,Inputs!$D$21)-Inputs!$C$21)*MAX(Inputs!$C$11,ROUND((Inputs!$C$6+2*Inputs!$C$7)*(1-Inputs!$C$8)^(($B10-Inputs!$C$10)/Inputs!$C$9),1))+MAX(0,MIN(F$5,Inputs!$D$22)-Inputs!$C$22)*MAX(Inputs!$C$11,ROUND((Inputs!$C$6+3*Inputs!$C$7)*(1-Inputs!$C$8)^(($B10-Inputs!$C$10)/Inputs!$C$9),1))+MAX(0,MIN(F$5,Inputs!$D$23)-Inputs!$C$23)*MAX(Inputs!$C$11,ROUND((Inputs!$C$6+4*Inputs!$C$7)*(1-Inputs!$C$8)^(($B10-Inputs!$C$10)/Inputs!$C$9),1)))/F$5) | G10: =IF(G$5<$B10,"",(MAX(0,MIN(G$5,Inputs!$D$19)-Inputs!$C$19)*MAX(Inputs!$C$11,ROUND((Inputs!$C$6+0*Inputs!$C$7)*(1-Inputs!$C$8)^(($B10-Inputs!$C$10)/Inputs!$C$9),1))+MAX(0,MIN(G$5,Inputs!$D$20)-Inputs!$C$20)*MAX(Inputs!$C$11,ROUND((Inputs!$C$6+1*Inputs!$C$7)*(1-Inputs!$C$8)^(($B10-Inputs!$C$10)/Inputs!$C$9),1))+MAX(0,MIN(G$5,Inputs!$D$21)-Inputs!$C$21)*MAX(Inputs!$C$11,ROUND((Inputs!$C$6+2*Inputs!$C$7)*(1-Inputs!$C$8)^(($B10-Inputs!$C$10)/Inputs!$C$9),1))+MAX(0,MIN(G$5,Inputs!$D$22)-Inputs!$C$22)*MAX(Inputs!$C$11,ROUND((Inputs!$C$6+3*Inputs!$C$7)*(1-Inputs!$C$8)^(($B10-Inputs!$C$10)/Inputs!$C$9),1))+MAX(0,MIN(G$5,Inputs!$D$23)-Inputs!$C$23)*MAX(Inputs!$C$11,ROUND((Inputs!$C$6+4*Inputs!$C$7)*(1-Inputs!$C$8)^(($B10-Inputs!$C$10)/Inputs!$C$9),1)))/G$5) | H10: =IF(H$5<$B10,"",(MAX(0,MIN(H$5,Inputs!$D$19)-Inputs!$C$19)*MAX(Inputs!$C$11,ROUND((Inputs!$C$6+0*Inputs!$C$7)*(1-Inputs!$C$8)^(($B10-Inputs!$C$10)/Inputs!$C$9),1))+MAX(0,MIN(H$5,Inputs!$D$20)-Inputs!$C$20)*MAX(Inputs!$C$11,ROUND((Inputs!$C$6+1*Inputs!$C$7)*(1-Inputs!$C$8)^(($B10-Inputs!$C$10)/Inputs!$C$9),1))+MAX(0,MIN(H$5,Inputs!$D$21)-Inputs!$C$21)*MAX(Inputs!$C$11,ROUND((Inputs!$C$6+2*Inputs!$C$7)*(1-Inputs!$C$8)^(($B10-Inputs!$C$10)/Inputs!$C$9),1))+MAX(0,MIN(H$5,Inputs!$D$22)-Inputs!$C$22)*MAX(Inputs!$C$11,ROUND((Inputs!$C$6+3*Inputs!$C$7)*(1-Inputs!$C$8)^(($B10-Inputs!$C$10)/Inputs!$C$9),1))+MAX(0,MIN(H$5,Inputs!$D$23)-Inputs!$C$23)*MAX(Inputs!$C$11,ROUND((Inputs!$C$6+4*Inputs!$C$7)*(1-Inputs!$C$8)^(($B10-Inputs!$C$10)/Inputs!$C$9),1)))/H$5)
B11: 60000 | C11: =IF(C$5<$B11,"",(MAX(0,MIN(C$5,Inputs!$D$19)-Inputs!$C$19)*MAX(Inputs!$C$11,ROUND((Inputs!$C$6+0*Inputs!$C$7)*(1-Inputs!$C$8)^(($B11-Inputs!$C$10)/Inputs!$C$9),1))+MAX(0,MIN(C$5,Inputs!$D$20)-Inputs!$C$20)*MAX(Inputs!$C$11,ROUND((Inputs!$C$6+1*Inputs!$C$7)*(1-Inputs!$C$8)^(($B11-Inputs!$C$10)/Inputs!$C$9),1))+MAX(0,MIN(C$5,Inputs!$D$21)-Inputs!$C$21)*MAX(Inputs!$C$11,ROUND((Inputs!$C$6+2*Inputs!$C$7)*(1-Inputs!$C$8)^(($B11-Inputs!$C$10)/Inputs!$C$9),1))+MAX(0,MIN(C$5,Inputs!$D$22)-Inputs!$C$22)*MAX(Inputs!$C$11,ROUND((Inputs!$C$6+3*Inputs!$C$7)*(1-Inputs!$C$8)^(($B11-Inputs!$C$10)/Inputs!$C$9),1))+MAX(0,MIN(C$5,Inputs!$D$23)-Inputs!$C$23)*MAX(Inputs!$C$11,ROUND((Inputs!$C$6+4*Inputs!$C$7)*(1-Inputs!$C$8)^(($B11-Inputs!$C$10)/Inputs!$C$9),1)))/C$5) | D11: =IF(D$5<$B11,"",(MAX(0,MIN(D$5,Inputs!$D$19)-Inputs!$C$19)*MAX(Inputs!$C$11,ROUND((Inputs!$C$6+0*Inputs!$C$7)*(1-Inputs!$C$8)^(($B11-Inputs!$C$10)/Inputs!$C$9),1))+MAX(0,MIN(D$5,Inputs!$D$20)-Inputs!$C$20)*MAX(Inputs!$C$11,ROUND((Inputs!$C$6+1*Inputs!$C$7)*(1-Inputs!$C$8)^(($B11-Inputs!$C$10)/Inputs!$C$9),1))+MAX(0,MIN(D$5,Inputs!$D$21)-Inputs!$C$21)*MAX(Inputs!$C$11,ROUND((Inputs!$C$6+2*Inputs!$C$7)*(1-Inputs!$C$8)^(($B11-Inputs!$C$10)/Inputs!$C$9),1))+MAX(0,MIN(D$5,Inputs!$D$22)-Inputs!$C$22)*MAX(Inputs!$C$11,ROUND((Inputs!$C$6+3*Inputs!$C$7)*(1-Inputs!$C$8)^(($B11-Inputs!$C$10)/Inputs!$C$9),1))+MAX(0,MIN(D$5,Inputs!$D$23)-Inputs!$C$23)*MAX(Inputs!$C$11,ROUND((Inputs!$C$6+4*Inputs!$C$7)*(1-Inputs!$C$8)^(($B11-Inputs!$C$10)/Inputs!$C$9),1)))/D$5) | E11: =IF(E$5<$B11,"",(MAX(0,MIN(E$5,Inputs!$D$19)-Inputs!$C$19)*MAX(Inputs!$C$11,ROUND((Inputs!$C$6+0*Inputs!$C$7)*(1-Inputs!$C$8)^(($B11-Inputs!$C$10)/Inputs!$C$9),1))+MAX(0,MIN(E$5,Inputs!$D$20)-Inputs!$C$20)*MAX(Inputs!$C$11,ROUND((Inputs!$C$6+1*Inputs!$C$7)*(1-Inputs!$C$8)^(($B11-Inputs!$C$10)/Inputs!$C$9),1))+MAX(0,MIN(E$5,Inputs!$D$21)-Inputs!$C$21)*MAX(Inputs!$C$11,ROUND((Inputs!$C$6+2*Inputs!$C$7)*(1-Inputs!$C$8)^(($B11-Inputs!$C$10)/Inputs!$C$9),1))+MAX(0,MIN(E$5,Inputs!$D$22)-Inputs!$C$22)*MAX(Inputs!$C$11,ROUND((Inputs!$C$6+3*Inputs!$C$7)*(1-Inputs!$C$8)^(($B11-Inputs!$C$10)/Inputs!$C$9),1))+MAX(0,MIN(E$5,Inputs!$D$23)-Inputs!$C$23)*MAX(Inputs!$C$11,ROUND((Inputs!$C$6+4*Inputs!$C$7)*(1-Inputs!$C$8)^(($B11-Inputs!$C$10)/Inputs!$C$9),1)))/E$5) | F11: =IF(F$5<$B11,"",(MAX(0,MIN(F$5,Inputs!$D$19)-Inputs!$C$19)*MAX(Inputs!$C$11,ROUND((Inputs!$C$6+0*Inputs!$C$7)*(1-Inputs!$C$8)^(($B11-Inputs!$C$10)/Inputs!$C$9),1))+MAX(0,MIN(F$5,Inputs!$D$20)-Inputs!$C$20)*MAX(Inputs!$C$11,ROUND((Inputs!$C$6+1*Inputs!$C$7)*(1-Inputs!$C$8)^(($B11-Inputs!$C$10)/Inputs!$C$9),1))+MAX(0,MIN(F$5,Inputs!$D$21)-Inputs!$C$21)*MAX(Inputs!$C$11,ROUND((Inputs!$C$6+2*Inputs!$C$7)*(1-Inputs!$C$8)^(($B11-Inputs!$C$10)/Inputs!$C$9),1))+MAX(0,MIN(F$5,Inputs!$D$22)-Inputs!$C$22)*MAX(Inputs!$C$11,ROUND((Inputs!$C$6+3*Inputs!$C$7)*(1-Inputs!$C$8)^(($B11-Inputs!$C$10)/Inputs!$C$9),1))+MAX(0,MIN(F$5,Inputs!$D$23)-Inputs!$C$23)*MAX(Inputs!$C$11,ROUND((Inputs!$C$6+4*Inputs!$C$7)*(1-Inputs!$C$8)^(($B11-Inputs!$C$10)/Inputs!$C$9),1)))/F$5) | G11: =IF(G$5<$B11,"",(MAX(0,MIN(G$5,Inputs!$D$19)-Inputs!$C$19)*MAX(Inputs!$C$11,ROUND((Inputs!$C$6+0*Inputs!$C$7)*(1-Inputs!$C$8)^(($B11-Inputs!$C$10)/Inputs!$C$9),1))+MAX(0,MIN(G$5,Inputs!$D$20)-Inputs!$C$20)*MAX(Inputs!$C$11,ROUND((Inputs!$C$6+1*Inputs!$C$7)*(1-Inputs!$C$8)^(($B11-Inputs!$C$10)/Inputs!$C$9),1))+MAX(0,MIN(G$5,Inputs!$D$21)-Inputs!$C$21)*MAX(Inputs!$C$11,ROUND((Inputs!$C$6+2*Inputs!$C$7)*(1-Inputs!$C$8)^(($B11-Inputs!$C$10)/Inputs!$C$9),1))+MAX(0,MIN(G$5,Inputs!$D$22)-Inputs!$C$22)*MAX(Inputs!$C$11,ROUND((Inputs!$C$6+3*Inputs!$C$7)*(1-Inputs!$C$8)^(($B11-Inputs!$C$10)/Inputs!$C$9),1))+MAX(0,MIN(G$5,Inputs!$D$23)-Inputs!$C$23)*MAX(Inputs!$C$11,ROUND((Inputs!$C$6+4*Inputs!$C$7)*(1-Inputs!$C$8)^(($B11-Inputs!$C$10)/Inputs!$C$9),1)))/G$5) | H11: =IF(H$5<$B11,"",(MAX(0,MIN(H$5,Inputs!$D$19)-Inputs!$C$19)*MAX(Inputs!$C$11,ROUND((Inputs!$C$6+0*Inputs!$C$7)*(1-Inputs!$C$8)^(($B11-Inputs!$C$10)/Inputs!$C$9),1))+MAX(0,MIN(H$5,Inputs!$D$20)-Inputs!$C$20)*MAX(Inputs!$C$11,ROUND((Inputs!$C$6+1*Inputs!$C$7)*(1-Inputs!$C$8)^(($B11-Inputs!$C$10)/Inputs!$C$9),1))+MAX(0,MIN(H$5,Inputs!$D$21)-Inputs!$C$21)*MAX(Inputs!$C$11,ROUND((Inputs!$C$6+2*Inputs!$C$7)*(1-Inputs!$C$8)^(($B11-Inputs!$C$10)/Inputs!$C$9),1))+MAX(0,MIN(H$5,Inputs!$D$22)-Inputs!$C$22)*MAX(Inputs!$C$11,ROUND((Inputs!$C$6+3*Inputs!$C$7)*(1-Inputs!$C$8)^(($B11-Inputs!$C$10)/Inputs!$C$9),1))+MAX(0,MIN(H$5,Inputs!$D$23)-Inputs!$C$23)*MAX(Inputs!$C$11,ROUND((Inputs!$C$6+4*Inputs!$C$7)*(1-Inputs!$C$8)^(($B11-Inputs!$C$10)/Inputs!$C$9),1)))/H$5)
B12: 70000 | C12: =IF(C$5<$B12,"",(MAX(0,MIN(C$5,Inputs!$D$19)-Inputs!$C$19)*MAX(Inputs!$C$11,ROUND((Inputs!$C$6+0*Inputs!$C$7)*(1-Inputs!$C$8)^(($B12-Inputs!$C$10)/Inputs!$C$9),1))+MAX(0,MIN(C$5,Inputs!$D$20)-Inputs!$C$20)*MAX(Inputs!$C$11,ROUND((Inputs!$C$6+1*Inputs!$C$7)*(1-Inputs!$C$8)^(($B12-Inputs!$C$10)/Inputs!$C$9),1))+MAX(0,MIN(C$5,Inputs!$D$21)-Inputs!$C$21)*MAX(Inputs!$C$11,ROUND((Inputs!$C$6+2*Inputs!$C$7)*(1-Inputs!$C$8)^(($B12-Inputs!$C$10)/Inputs!$C$9),1))+MAX(0,MIN(C$5,Inputs!$D$22)-Inputs!$C$22)*MAX(Inputs!$C$11,ROUND((Inputs!$C$6+3*Inputs!$C$7)*(1-Inputs!$C$8)^(($B12-Inputs!$C$10)/Inputs!$C$9),1))+MAX(0,MIN(C$5,Inputs!$D$23)-Inputs!$C$23)*MAX(Inputs!$C$11,ROUND((Inputs!$C$6+4*Inputs!$C$7)*(1-Inputs!$C$8)^(($B12-Inputs!$C$10)/Inputs!$C$9),1)))/C$5) | D12: =IF(D$5<$B12,"",(MAX(0,MIN(D$5,Inputs!$D$19)-Inputs!$C$19)*MAX(Inputs!$C$11,ROUND((Inputs!$C$6+0*Inputs!$C$7)*(1-Inputs!$C$8)^(($B12-Inputs!$C$10)/Inputs!$C$9),1))+MAX(0,MIN(D$5,Inputs!$D$20)-Inputs!$C$20)*MAX(Inputs!$C$11,ROUND((Inputs!$C$6+1*Inputs!$C$7)*(1-Inputs!$C$8)^(($B12-Inputs!$C$10)/Inputs!$C$9),1))+MAX(0,MIN(D$5,Inputs!$D$21)-Inputs!$C$21)*MAX(Inputs!$C$11,ROUND((Inputs!$C$6+2*Inputs!$C$7)*(1-Inputs!$C$8)^(($B12-Inputs!$C$10)/Inputs!$C$9),1))+MAX(0,MIN(D$5,Inputs!$D$22)-Inputs!$C$22)*MAX(Inputs!$C$11,ROUND((Inputs!$C$6+3*Inputs!$C$7)*(1-Inputs!$C$8)^(($B12-Inputs!$C$10)/Inputs!$C$9),1))+MAX(0,MIN(D$5,Inputs!$D$23)-Inputs!$C$23)*MAX(Inputs!$C$11,ROUND((Inputs!$C$6+4*Inputs!$C$7)*(1-Inputs!$C$8)^(($B12-Inputs!$C$10)/Inputs!$C$9),1)))/D$5) | E12: =IF(E$5<$B12,"",(MAX(0,MIN(E$5,Inputs!$D$19)-Inputs!$C$19)*MAX(Inputs!$C$11,ROUND((Inputs!$C$6+0*Inputs!$C$7)*(1-Inputs!$C$8)^(($B12-Inputs!$C$10)/Inputs!$C$9),1))+MAX(0,MIN(E$5,Inputs!$D$20)-Inputs!$C$20)*MAX(Inputs!$C$11,ROUND((Inputs!$C$6+1*Inputs!$C$7)*(1-Inputs!$C$8)^(($B12-Inputs!$C$10)/Inputs!$C$9),1))+MAX(0,MIN(E$5,Inputs!$D$21)-Inputs!$C$21)*MAX(Inputs!$C$11,ROUND((Inputs!$C$6+2*Inputs!$C$7)*(1-Inputs!$C$8)^(($B12-Inputs!$C$10)/Inputs!$C$9),1))+MAX(0,MIN(E$5,Inputs!$D$22)-Inputs!$C$22)*MAX(Inputs!$C$11,ROUND((Inputs!$C$6+3*Inputs!$C$7)*(1-Inputs!$C$8)^(($B12-Inputs!$C$10)/Inputs!$C$9),1))+MAX(0,MIN(E$5,Inputs!$D$23)-Inputs!$C$23)*MAX(Inputs!$C$11,ROUND((Inputs!$C$6+4*Inputs!$C$7)*(1-Inputs!$C$8)^(($B12-Inputs!$C$10)/Inputs!$C$9),1)))/E$5) | F12: =IF(F$5<$B12,"",(MAX(0,MIN(F$5,Inputs!$D$19)-Inputs!$C$19)*MAX(Inputs!$C$11,ROUND((Inputs!$C$6+0*Inputs!$C$7)*(1-Inputs!$C$8)^(($B12-Inputs!$C$10)/Inputs!$C$9),1))+MAX(0,MIN(F$5,Inputs!$D$20)-Inputs!$C$20)*MAX(Inputs!$C$11,ROUND((Inputs!$C$6+1*Inputs!$C$7)*(1-Inputs!$C$8)^(($B12-Inputs!$C$10)/Inputs!$C$9),1))+MAX(0,MIN(F$5,Inputs!$D$21)-Inputs!$C$21)*MAX(Inputs!$C$11,ROUND((Inputs!$C$6+2*Inputs!$C$7)*(1-Inputs!$C$8)^(($B12-Inputs!$C$10)/Inputs!$C$9),1))+MAX(0,MIN(F$5,Inputs!$D$22)-Inputs!$C$22)*MAX(Inputs!$C$11,ROUND((Inputs!$C$6+3*Inputs!$C$7)*(1-Inputs!$C$8)^(($B12-Inputs!$C$10)/Inputs!$C$9),1))+MAX(0,MIN(F$5,Inputs!$D$23)-Inputs!$C$23)*MAX(Inputs!$C$11,ROUND((Inputs!$C$6+4*Inputs!$C$7)*(1-Inputs!$C$8)^(($B12-Inputs!$C$10)/Inputs!$C$9),1)))/F$5) | G12: =IF(G$5<$B12,"",(MAX(0,MIN(G$5,Inputs!$D$19)-Inputs!$C$19)*MAX(Inputs!$C$11,ROUND((Inputs!$C$6+0*Inputs!$C$7)*(1-Inputs!$C$8)^(($B12-Inputs!$C$10)/Inputs!$C$9),1))+MAX(0,MIN(G$5,Inputs!$D$20)-Inputs!$C$20)*MAX(Inputs!$C$11,ROUND((Inputs!$C$6+1*Inputs!$C$7)*(1-Inputs!$C$8)^(($B12-Inputs!$C$10)/Inputs!$C$9),1))+MAX(0,MIN(G$5,Inputs!$D$21)-Inputs!$C$21)*MAX(Inputs!$C$11,ROUND((Inputs!$C$6+2*Inputs!$C$7)*(1-Inputs!$C$8)^(($B12-Inputs!$C$10)/Inputs!$C$9),1))+MAX(0,MIN(G$5,Inputs!$D$22)-Inputs!$C$22)*MAX(Inputs!$C$11,ROUND((Inputs!$C$6+3*Inputs!$C$7)*(1-Inputs!$C$8)^(($B12-Inputs!$C$10)/Inputs!$C$9),1))+MAX(0,MIN(G$5,Inputs!$D$23)-Inputs!$C$23)*MAX(Inputs!$C$11,ROUND((Inputs!$C$6+4*Inputs!$C$7)*(1-Inputs!$C$8)^(($B12-Inputs!$C$10)/Inputs!$C$9),1)))/G$5) | H12: =IF(H$5<$B12,"",(MAX(0,MIN(H$5,Inputs!$D$19)-Inputs!$C$19)*MAX(Inputs!$C$11,ROUND((Inputs!$C$6+0*Inputs!$C$7)*(1-Inputs!$C$8)^(($B12-Inputs!$C$10)/Inputs!$C$9),1))+MAX(0,MIN(H$5,Inputs!$D$20)-Inputs!$C$20)*MAX(Inputs!$C$11,ROUND((Inputs!$C$6+1*Inputs!$C$7)*(1-Inputs!$C$8)^(($B12-Inputs!$C$10)/Inputs!$C$9),1))+MAX(0,MIN(H$5,Inputs!$D$21)-Inputs!$C$21)*MAX(Inputs!$C$11,ROUND((Inputs!$C$6+2*Inputs!$C$7)*(1-Inputs!$C$8)^(($B12-Inputs!$C$10)/Inputs!$C$9),1))+MAX(0,MIN(H$5,Inputs!$D$22)-Inputs!$C$22)*MAX(Inputs!$C$11,ROUND((Inputs!$C$6+3*Inputs!$C$7)*(1-Inputs!$C$8)^(($B12-Inputs!$C$10)/Inputs!$C$9),1))+MAX(0,MIN(H$5,Inputs!$D$23)-Inputs!$C$23)*MAX(Inputs!$C$11,ROUND((Inputs!$C$6+4*Inputs!$C$7)*(1-Inputs!$C$8)^(($B12-Inputs!$C$10)/Inputs!$C$9),1)))/H$5)
B13: 80000 | C13: =IF(C$5<$B13,"",(MAX(0,MIN(C$5,Inputs!$D$19)-Inputs!$C$19)*MAX(Inputs!$C$11,ROUND((Inputs!$C$6+0*Inputs!$C$7)*(1-Inputs!$C$8)^(($B13-Inputs!$C$10)/Inputs!$C$9),1))+MAX(0,MIN(C$5,Inputs!$D$20)-Inputs!$C$20)*MAX(Inputs!$C$11,ROUND((Inputs!$C$6+1*Inputs!$C$7)*(1-Inputs!$C$8)^(($B13-Inputs!$C$10)/Inputs!$C$9),1))+MAX(0,MIN(C$5,Inputs!$D$21)-Inputs!$C$21)*MAX(Inputs!$C$11,ROUND((Inputs!$C$6+2*Inputs!$C$7)*(1-Inputs!$C$8)^(($B13-Inputs!$C$10)/Inputs!$C$9),1))+MAX(0,MIN(C$5,Inputs!$D$22)-Inputs!$C$22)*MAX(Inputs!$C$11,ROUND((Inputs!$C$6+3*Inputs!$C$7)*(1-Inputs!$C$8)^(($B13-Inputs!$C$10)/Inputs!$C$9),1))+MAX(0,MIN(C$5,Inputs!$D$23)-Inputs!$C$23)*MAX(Inputs!$C$11,ROUND((Inputs!$C$6+4*Inputs!$C$7)*(1-Inputs!$C$8)^(($B13-Inputs!$C$10)/Inputs!$C$9),1)))/C$5) | D13: =IF(D$5<$B13,"",(MAX(0,MIN(D$5,Inputs!$D$19)-Inputs!$C$19)*MAX(Inputs!$C$11,ROUND((Inputs!$C$6+0*Inputs!$C$7)*(1-Inputs!$C$8)^(($B13-Inputs!$C$10)/Inputs!$C$9),1))+MAX(0,MIN(D$5,Inputs!$D$20)-Inputs!$C$20)*MAX(Inputs!$C$11,ROUND((Inputs!$C$6+1*Inputs!$C$7)*(1-Inputs!$C$8)^(($B13-Inputs!$C$10)/Inputs!$C$9),1))+MAX(0,MIN(D$5,Inputs!$D$21)-Inputs!$C$21)*MAX(Inputs!$C$11,ROUND((Inputs!$C$6+2*Inputs!$C$7)*(1-Inputs!$C$8)^(($B13-Inputs!$C$10)/Inputs!$C$9),1))+MAX(0,MIN(D$5,Inputs!$D$22)-Inputs!$C$22)*MAX(Inputs!$C$11,ROUND((Inputs!$C$6+3*Inputs!$C$7)*(1-Inputs!$C$8)^(($B13-Inputs!$C$10)/Inputs!$C$9),1))+MAX(0,MIN(D$5,Inputs!$D$23)-Inputs!$C$23)*MAX(Inputs!$C$11,ROUND((Inputs!$C$6+4*Inputs!$C$7)*(1-Inputs!$C$8)^(($B13-Inputs!$C$10)/Inputs!$C$9),1)))/D$5) | E13: =IF(E$5<$B13,"",(MAX(0,MIN(E$5,Inputs!$D$19)-Inputs!$C$19)*MAX(Inputs!$C$11,ROUND((Inputs!$C$6+0*Inputs!$C$7)*(1-Inputs!$C$8)^(($B13-Inputs!$C$10)/Inputs!$C$9),1))+MAX(0,MIN(E$5,Inputs!$D$20)-Inputs!$C$20)*MAX(Inputs!$C$11,ROUND((Inputs!$C$6+1*Inputs!$C$7)*(1-Inputs!$C$8)^(($B13-Inputs!$C$10)/Inputs!$C$9),1))+MAX(0,MIN(E$5,Inputs!$D$21)-Inputs!$C$21)*MAX(Inputs!$C$11,ROUND((Inputs!$C$6+2*Inputs!$C$7)*(1-Inputs!$C$8)^(($B13-Inputs!$C$10)/Inputs!$C$9),1))+MAX(0,MIN(E$5,Inputs!$D$22)-Inputs!$C$22)*MAX(Inputs!$C$11,ROUND((Inputs!$C$6+3*Inputs!$C$7)*(1-Inputs!$C$8)^(($B13-Inputs!$C$10)/Inputs!$C$9),1))+MAX(0,MIN(E$5,Inputs!$D$23)-Inputs!$C$23)*MAX(Inputs!$C$11,ROUND((Inputs!$C$6+4*Inputs!$C$7)*(1-Inputs!$C$8)^(($B13-Inputs!$C$10)/Inputs!$C$9),1)))/E$5) | F13: =IF(F$5<$B13,"",(MAX(0,MIN(F$5,Inputs!$D$19)-Inputs!$C$19)*MAX(Inputs!$C$11,ROUND((Inputs!$C$6+0*Inputs!$C$7)*(1-Inputs!$C$8)^(($B13-Inputs!$C$10)/Inputs!$C$9),1))+MAX(0,MIN(F$5,Inputs!$D$20)-Inputs!$C$20)*MAX(Inputs!$C$11,ROUND((Inputs!$C$6+1*Inputs!$C$7)*(1-Inputs!$C$8)^(($B13-Inputs!$C$10)/Inputs!$C$9),1))+MAX(0,MIN(F$5,Inputs!$D$21)-Inputs!$C$21)*MAX(Inputs!$C$11,ROUND((Inputs!$C$6+2*Inputs!$C$7)*(1-Inputs!$C$8)^(($B13-Inputs!$C$10)/Inputs!$C$9),1))+MAX(0,MIN(F$5,Inputs!$D$22)-Inputs!$C$22)*MAX(Inputs!$C$11,ROUND((Inputs!$C$6+3*Inputs!$C$7)*(1-Inputs!$C$8)^(($B13-Inputs!$C$10)/Inputs!$C$9),1))+MAX(0,MIN(F$5,Inputs!$D$23)-Inputs!$C$23)*MAX(Inputs!$C$11,ROUND((Inputs!$C$6+4*Inputs!$C$7)*(1-Inputs!$C$8)^(($B13-Inputs!$C$10)/Inputs!$C$9),1)))/F$5) | G13: =IF(G$5<$B13,"",(MAX(0,MIN(G$5,Inputs!$D$19)-Inputs!$C$19)*MAX(Inputs!$C$11,ROUND((Inputs!$C$6+0*Inputs!$C$7)*(1-Inputs!$C$8)^(($B13-Inputs!$C$10)/Inputs!$C$9),1))+MAX(0,MIN(G$5,Inputs!$D$20)-Inputs!$C$20)*MAX(Inputs!$C$11,ROUND((Inputs!$C$6+1*Inputs!$C$7)*(1-Inputs!$C$8)^(($B13-Inputs!$C$10)/Inputs!$C$9),1))+MAX(0,MIN(G$5,Inputs!$D$21)-Inputs!$C$21)*MAX(Inputs!$C$11,ROUND((Inputs!$C$6+2*Inputs!$C$7)*(1-Inputs!$C$8)^(($B13-Inputs!$C$10)/Inputs!$C$9),1))+MAX(0,MIN(G$5,Inputs!$D$22)-Inputs!$C$22)*MAX(Inputs!$C$11,ROUND((Inputs!$C$6+3*Inputs!$C$7)*(1-Inputs!$C$8)^(($B13-Inputs!$C$10)/Inputs!$C$9),1))+MAX(0,MIN(G$5,Inputs!$D$23)-Inputs!$C$23)*MAX(Inputs!$C$11,ROUND((Inputs!$C$6+4*Inputs!$C$7)*(1-Inputs!$C$8)^(($B13-Inputs!$C$10)/Inputs!$C$9),1)))/G$5) | H13: =IF(H$5<$B13,"",(MAX(0,MIN(H$5,Inputs!$D$19)-Inputs!$C$19)*MAX(Inputs!$C$11,ROUND((Inputs!$C$6+0*Inputs!$C$7)*(1-Inputs!$C$8)^(($B13-Inputs!$C$10)/Inputs!$C$9),1))+MAX(0,MIN(H$5,Inputs!$D$20)-Inputs!$C$20)*MAX(Inputs!$C$11,ROUND((Inputs!$C$6+1*Inputs!$C$7)*(1-Inputs!$C$8)^(($B13-Inputs!$C$10)/Inputs!$C$9),1))+MAX(0,MIN(H$5,Inputs!$D$21)-Inputs!$C$21)*MAX(Inputs!$C$11,ROUND((Inputs!$C$6+2*Inputs!$C$7)*(1-Inputs!$C$8)^(($B13-Inputs!$C$10)/Inputs!$C$9),1))+MAX(0,MIN(H$5,Inputs!$D$22)-Inputs!$C$22)*MAX(Inputs!$C$11,ROUND((Inputs!$C$6+3*Inputs!$C$7)*(1-Inputs!$C$8)^(($B13-Inputs!$C$10)/Inputs!$C$9),1))+MAX(0,MIN(H$5,Inputs!$D$23)-Inputs!$C$23)*MAX(Inputs!$C$11,ROUND((Inputs!$C$6+4*Inputs!$C$7)*(1-Inputs!$C$8)^(($B13-Inputs!$C$10)/Inputs!$C$9),1)))/H$5)
B14: 90000 | C14: =IF(C$5<$B14,"",(MAX(0,MIN(C$5,Inputs!$D$19)-Inputs!$C$19)*MAX(Inputs!$C$11,ROUND((Inputs!$C$6+0*Inputs!$C$7)*(1-Inputs!$C$8)^(($B14-Inputs!$C$10)/Inputs!$C$9),1))+MAX(0,MIN(C$5,Inputs!$D$20)-Inputs!$C$20)*MAX(Inputs!$C$11,ROUND((Inputs!$C$6+1*Inputs!$C$7)*(1-Inputs!$C$8)^(($B14-Inputs!$C$10)/Inputs!$C$9),1))+MAX(0,MIN(C$5,Inputs!$D$21)-Inputs!$C$21)*MAX(Inputs!$C$11,ROUND((Inputs!$C$6+2*Inputs!$C$7)*(1-Inputs!$C$8)^(($B14-Inputs!$C$10)/Inputs!$C$9),1))+MAX(0,MIN(C$5,Inputs!$D$22)-Inputs!$C$22)*MAX(Inputs!$C$11,ROUND((Inputs!$C$6+3*Inputs!$C$7)*(1-Inputs!$C$8)^(($B14-Inputs!$C$10)/Inputs!$C$9),1))+MAX(0,MIN(C$5,Inputs!$D$23)-Inputs!$C$23)*MAX(Inputs!$C$11,ROUND((Inputs!$C$6+4*Inputs!$C$7)*(1-Inputs!$C$8)^(($B14-Inputs!$C$10)/Inputs!$C$9),1)))/C$5) | D14: =IF(D$5<$B14,"",(MAX(0,MIN(D$5,Inputs!$D$19)-Inputs!$C$19)*MAX(Inputs!$C$11,ROUND((Inputs!$C$6+0*Inputs!$C$7)*(1-Inputs!$C$8)^(($B14-Inputs!$C$10)/Inputs!$C$9),1))+MAX(0,MIN(D$5,Inputs!$D$20)-Inputs!$C$20)*MAX(Inputs!$C$11,ROUND((Inputs!$C$6+1*Inputs!$C$7)*(1-Inputs!$C$8)^(($B14-Inputs!$C$10)/Inputs!$C$9),1))+MAX(0,MIN(D$5,Inputs!$D$21)-Inputs!$C$21)*MAX(Inputs!$C$11,ROUND((Inputs!$C$6+2*Inputs!$C$7)*(1-Inputs!$C$8)^(($B14-Inputs!$C$10)/Inputs!$C$9),1))+MAX(0,MIN(D$5,Inputs!$D$22)-Inputs!$C$22)*MAX(Inputs!$C$11,ROUND((Inputs!$C$6+3*Inputs!$C$7)*(1-Inputs!$C$8)^(($B14-Inputs!$C$10)/Inputs!$C$9),1))+MAX(0,MIN(D$5,Inputs!$D$23)-Inputs!$C$23)*MAX(Inputs!$C$11,ROUND((Inputs!$C$6+4*Inputs!$C$7)*(1-Inputs!$C$8)^(($B14-Inputs!$C$10)/Inputs!$C$9),1)))/D$5) | E14: =IF(E$5<$B14,"",(MAX(0,MIN(E$5,Inputs!$D$19)-Inputs!$C$19)*MAX(Inputs!$C$11,ROUND((Inputs!$C$6+0*Inputs!$C$7)*(1-Inputs!$C$8)^(($B14-Inputs!$C$10)/Inputs!$C$9),1))+MAX(0,MIN(E$5,Inputs!$D$20)-Inputs!$C$20)*MAX(Inputs!$C$11,ROUND((Inputs!$C$6+1*Inputs!$C$7)*(1-Inputs!$C$8)^(($B14-Inputs!$C$10)/Inputs!$C$9),1))+MAX(0,MIN(E$5,Inputs!$D$21)-Inputs!$C$21)*MAX(Inputs!$C$11,ROUND((Inputs!$C$6+2*Inputs!$C$7)*(1-Inputs!$C$8)^(($B14-Inputs!$C$10)/Inputs!$C$9),1))+MAX(0,MIN(E$5,Inputs!$D$22)-Inputs!$C$22)*MAX(Inputs!$C$11,ROUND((Inputs!$C$6+3*Inputs!$C$7)*(1-Inputs!$C$8)^(($B14-Inputs!$C$10)/Inputs!$C$9),1))+MAX(0,MIN(E$5,Inputs!$D$23)-Inputs!$C$23)*MAX(Inputs!$C$11,ROUND((Inputs!$C$6+4*Inputs!$C$7)*(1-Inputs!$C$8)^(($B14-Inputs!$C$10)/Inputs!$C$9),1)))/E$5) | F14: =IF(F$5<$B14,"",(MAX(0,MIN(F$5,Inputs!$D$19)-Inputs!$C$19)*MAX(Inputs!$C$11,ROUND((Inputs!$C$6+0*Inputs!$C$7)*(1-Inputs!$C$8)^(($B14-Inputs!$C$10)/Inputs!$C$9),1))+MAX(0,MIN(F$5,Inputs!$D$20)-Inputs!$C$20)*MAX(Inputs!$C$11,ROUND((Inputs!$C$6+1*Inputs!$C$7)*(1-Inputs!$C$8)^(($B14-Inputs!$C$10)/Inputs!$C$9),1))+MAX(0,MIN(F$5,Inputs!$D$21)-Inputs!$C$21)*MAX(Inputs!$C$11,ROUND((Inputs!$C$6+2*Inputs!$C$7)*(1-Inputs!$C$8)^(($B14-Inputs!$C$10)/Inputs!$C$9),1))+MAX(0,MIN(F$5,Inputs!$D$22)-Inputs!$C$22)*MAX(Inputs!$C$11,ROUND((Inputs!$C$6+3*Inputs!$C$7)*(1-Inputs!$C$8)^(($B14-Inputs!$C$10)/Inputs!$C$9),1))+MAX(0,MIN(F$5,Inputs!$D$23)-Inputs!$C$23)*MAX(Inputs!$C$11,ROUND((Inputs!$C$6+4*Inputs!$C$7)*(1-Inputs!$C$8)^(($B14-Inputs!$C$10)/Inputs!$C$9),1)))/F$5) | G14: =IF(G$5<$B14,"",(MAX(0,MIN(G$5,Inputs!$D$19)-Inputs!$C$19)*MAX(Inputs!$C$11,ROUND((Inputs!$C$6+0*Inputs!$C$7)*(1-Inputs!$C$8)^(($B14-Inputs!$C$10)/Inputs!$C$9),1))+MAX(0,MIN(G$5,Inputs!$D$20)-Inputs!$C$20)*MAX(Inputs!$C$11,ROUND((Inputs!$C$6+1*Inputs!$C$7)*(1-Inputs!$C$8)^(($B14-Inputs!$C$10)/Inputs!$C$9),1))+MAX(0,MIN(G$5,Inputs!$D$21)-Inputs!$C$21)*MAX(Inputs!$C$11,ROUND((Inputs!$C$6+2*Inputs!$C$7)*(1-Inputs!$C$8)^(($B14-Inputs!$C$10)/Inputs!$C$9),1))+MAX(0,MIN(G$5,Inputs!$D$22)-Inputs!$C$22)*MAX(Inputs!$C$11,ROUND((Inputs!$C$6+3*Inputs!$C$7)*(1-Inputs!$C$8)^(($B14-Inputs!$C$10)/Inputs!$C$9),1))+MAX(0,MIN(G$5,Inputs!$D$23)-Inputs!$C$23)*MAX(Inputs!$C$11,ROUND((Inputs!$C$6+4*Inputs!$C$7)*(1-Inputs!$C$8)^(($B14-Inputs!$C$10)/Inputs!$C$9),1)))/G$5) | H14: =IF(H$5<$B14,"",(MAX(0,MIN(H$5,Inputs!$D$19)-Inputs!$C$19)*MAX(Inputs!$C$11,ROUND((Inputs!$C$6+0*Inputs!$C$7)*(1-Inputs!$C$8)^(($B14-Inputs!$C$10)/Inputs!$C$9),1))+MAX(0,MIN(H$5,Inputs!$D$20)-Inputs!$C$20)*MAX(Inputs!$C$11,ROUND((Inputs!$C$6+1*Inputs!$C$7)*(1-Inputs!$C$8)^(($B14-Inputs!$C$10)/Inputs!$C$9),1))+MAX(0,MIN(H$5,Inputs!$D$21)-Inputs!$C$21)*MAX(Inputs!$C$11,ROUND((Inputs!$C$6+2*Inputs!$C$7)*(1-Inputs!$C$8)^(($B14-Inputs!$C$10)/Inputs!$C$9),1))+MAX(0,MIN(H$5,Inputs!$D$22)-Inputs!$C$22)*MAX(Inputs!$C$11,ROUND((Inputs!$C$6+3*Inputs!$C$7)*(1-Inputs!$C$8)^(($B14-Inputs!$C$10)/Inputs!$C$9),1))+MAX(0,MIN(H$5,Inputs!$D$23)-Inputs!$C$23)*MAX(Inputs!$C$11,ROUND((Inputs!$C$6+4*Inputs!$C$7)*(1-Inputs!$C$8)^(($B14-Inputs!$C$10)/Inputs!$C$9),1)))/H$5)
